<?xml version="1.0" encoding="utf-8"?>
<!-- This URDF was automatically created by SolidWorks to URDF Exporter! Originally created by Stephen Brawner (brawner@gmail.com) 
     Commit Version: 1.6.0-4-g7f85cfe  Build Version: 1.6.7995.38578
     For more information, please see http://wiki.ros.org/sw_urdf_exporter -->
<robot
  name="full_amr">
  <link
    name="base_link">
    <inertial>
      <origin
        xyz="4.3964E-07 0.067797 -0.06095"
        rpy="0 0 0" />
      <mass
        value="3.8632" />
      <inertia
        ixx="0.066007"
        ixy="2.416E-08"
        ixz="-3.2997E-08"
        iyy="0.076685"
        iyz="1.2597E-07"
        izz="0.1421" />
    </inertial>
    <visual>
      <origin
        xyz="0 0 0"
        rpy="0 0 0" />
      <geometry>
        <mesh
          filename="package://full_amr/meshes/base_link.STL" />
      </geometry>
      <material
        name="">
        <color
          rgba="0.79216 0.81961 0.93333 1" />
      </material>
    </visual>
    <collision>
      <origin
        xyz="0 0 0"
        rpy="0 0 0" />
      <geometry>
        <mesh
          filename="package://full_amr/meshes/base_link.STL" />
      </geometry>
    </collision>
  </link>
  <link
    name="right_pivot">
    <inertial>
      <origin
        xyz="6.7225E-05 0.042261 0.014296"
        rpy="0 0 0" />
      <mass
        value="0.17398" />
      <inertia
        ixx="0.00035672"
        ixy="8.0021E-10"
        ixz="-7.7696E-08"
        iyy="6.8709E-05"
        iyz="3.4167E-06"
        izz="0.00038711" />
    </inertial>
    <visual>
      <origin
        xyz="0 0 0"
        rpy="0 0 0" />
      <geometry>
        <mesh
          filename="package://full_amr/meshes/right_pivot.STL" />
      </geometry>
      <material
        name="">
        <color
          rgba="0.79216 0.81961 0.93333 1" />
      </material>
    </visual>
    <collision>
      <origin
        xyz="0 0 0"
        rpy="0 0 0" />
      <geometry>
        <mesh
          filename="package://full_amr/meshes/right_pivot.STL" />
      </geometry>
    </collision>
  </link>
  <joint
    name="right_pivot_hinge"
    type="continuous">
    <origin
      xyz="0.1625 0.1275 -0.081"
      rpy="0 0 0" />
    <parent
      link="base_link" />
    <child
      link="right_pivot" />
    <axis
      xyz="1 0 0" />
  </joint>
  <link
    name="right_wheel">
    <inertial>
      <origin
        xyz="8.8292E-08 -1.8654E-08 -1.0762E-05"
        rpy="0 0 0" />
      <mass
        value="0.67187" />
      <inertia
        ixx="0.0015238"
        ixy="-2.9966E-09"
        ixz="-7.0839E-10"
        iyy="0.0015238"
        iyz="3.4601E-10"
        izz="0.0029142" />
    </inertial>
    <visual>
      <origin
        xyz="0 0 0"
        rpy="0 0 0" />
      <geometry>
        <mesh
          filename="package://full_amr/meshes/right_wheel.STL" />
      </geometry>
      <material
        name="">
        <color
          rgba="0.79216 0.81961 0.93333 1" />
      </material>
    </visual>
    <collision>
      <origin
        xyz="0 0 0"
        rpy="0 0 0" />
      <geometry>
        <mesh
          filename="package://full_amr/meshes/right_wheel.STL" />
      </geometry>
    </collision>
  </link>
  <joint
    name="right_wheel_hinge"
    type="continuous">
    <origin
      xyz="0.0606 -0.12783 -0.049416"
      rpy="1.5708 0 1.5708" />
    <parent
      link="right_pivot" />
    <child
      link="right_wheel" />
    <axis
      xyz="0 0 -1" />
  </joint>
  <link
    name="FR_swivel">
    <inertial>
      <origin
        xyz="2.1014E-06 -0.015845 -0.026318"
        rpy="0 0 0" />
      <mass
        value="0.040333" />
      <inertia
        ixx="4.7854E-05"
        ixy="-6.9028E-10"
        ixz="-4.4552E-10"
        iyy="5.1062E-05"
        iyz="-1.0892E-05"
        izz="4.8532E-05" />
    </inertial>
    <visual>
      <origin
        xyz="0 0 0"
        rpy="0 0 0" />
      <geometry>
        <mesh
          filename="package://full_amr/meshes/FR_swivel.STL" />
      </geometry>
      <material
        name="">
        <color
          rgba="0.79216 0.81961 0.93333 1" />
      </material>
    </visual>
    <collision>
      <origin
        xyz="0 0 0"
        rpy="0 0 0" />
      <geometry>
        <mesh
          filename="package://full_amr/meshes/FR_swivel.STL" />
      </geometry>
    </collision>
  </link>
  <joint
    name="FR_swivel_hinge"
    type="continuous">
    <origin
      xyz="0.000499999999999584 0.123056163560861 0.00819637783921516"
      rpy="0 0 0" />
    <parent
      link="right_pivot" />
    <child
      link="FR_swivel" />
    <axis
      xyz="0 0.00653195251969943 0.999978666570583" />
  </joint>
  <link
    name="FR_castor">
    <inertial>
      <origin
        xyz="2.1649E-14 -1.027E-15 1.8929E-14"
        rpy="0 0 0" />
      <mass
        value="0.1614" />
      <inertia
        ixx="0.0004168"
        ixy="2.7412E-18"
        ixz="-6.9496E-19"
        iyy="0.00022051"
        iyz="2.8267E-20"
        izz="0.00022051" />
    </inertial>
    <visual>
      <origin
        xyz="0 0 0"
        rpy="0 0 0" />
      <geometry>
        <mesh
          filename="package://full_amr/meshes/FR_castor.STL" />
      </geometry>
      <material
        name="">
        <color
          rgba="0.79216 0.81961 0.93333 1" />
      </material>
    </visual>
    <collision>
      <origin
        xyz="0 0 0"
        rpy="0 0 0" />
      <geometry>
        <mesh
          filename="package://full_amr/meshes/FR_castor.STL" />
      </geometry>
    </collision>
  </link>
  <joint
    name="FR_castor_hinge"
    type="continuous">
    <origin
      xyz="0.00099999999997849 -0.0425510539838774 -0.0842238553194065"
      rpy="0 0 0" />
    <parent
      link="FR_swivel" />
    <child
      link="FR_castor" />
    <axis
      xyz="1 0 0" />
  </joint>
  <link
    name="left_pivot">
    <inertial>
      <origin
        xyz="6.7225E-05 0.042152 0.014614"
        rpy="0 0 0" />
      <mass
        value="0.17398" />
      <inertia
        ixx="0.00035672"
        ixy="1.3844E-09"
        ixz="-7.7688E-08"
        iyy="6.8675E-05"
        iyz="1.0222E-06"
        izz="0.00038715" />
    </inertial>
    <visual>
      <origin
        xyz="0 0 0"
        rpy="0 0 0" />
      <geometry>
        <mesh
          filename="package://full_amr/meshes/left_pivot.STL" />
      </geometry>
      <material
        name="">
        <color
          rgba="0.79216 0.81961 0.93333 1" />
      </material>
    </visual>
    <collision>
      <origin
        xyz="0 0 0"
        rpy="0 0 0" />
      <geometry>
        <mesh
          filename="package://full_amr/meshes/left_pivot.STL" />
      </geometry>
    </collision>
  </link>
  <joint
    name="left_pivot_hinge"
    type="continuous">
    <origin
      xyz="-0.1625 0.1275 -0.081"
      rpy="0 0 0" />
    <parent
      link="base_link" />
    <child
      link="left_pivot" />
    <axis
      xyz="1 0 0" />
  </joint>
  <link
    name="left_wheel">
    <inertial>
      <origin
        xyz="5.1051E-08 7.4413E-08 -1.0762E-05"
        rpy="0 0 0" />
      <mass
        value="0.67187" />
      <inertia
        ixx="0.0015238"
        ixy="-1.2708E-09"
        ixz="-5.9097E-10"
        iyy="0.0015238"
        iyz="-5.2182E-10"
        izz="0.0029142" />
    </inertial>
    <visual>
      <origin
        xyz="0 0 0"
        rpy="0 0 0" />
      <geometry>
        <mesh
          filename="package://full_amr/meshes/left_wheel.STL" />
      </geometry>
      <material
        name="">
        <color
          rgba="0.79216 0.81961 0.93333 1" />
      </material>
    </visual>
    <collision>
      <origin
        xyz="0 0 0"
        rpy="0 0 0" />
      <geometry>
        <mesh
          filename="package://full_amr/meshes/left_wheel.STL" />
      </geometry>
    </collision>
  </link>
  <joint
    name="left_wheel_hinge"
    type="continuous">
    <origin
      xyz="-0.0606000000000003 -0.127450321712043 -0.050375867193494"
      rpy="3.14159265358979 -1.5707963267949 0" />
    <parent
      link="left_pivot" />
    <child
      link="left_wheel" />
    <axis
      xyz="0 0 -1" />
  </joint>
  <link
    name="FL_swivel">
    <inertial>
      <origin
        xyz="6.5512E-05 -0.015646 -0.026436"
        rpy="0 0 0" />
      <mass
        value="0.040333" />
      <inertia
        ixx="4.7854E-05"
        ixy="-1.4283E-08"
        ixz="4.3543E-08"
        iyy="5.1226E-05"
        iyz="-1.0871E-05"
        izz="4.8368E-05" />
    </inertial>
    <visual>
      <origin
        xyz="0 0 0"
        rpy="0 0 0" />
      <geometry>
        <mesh
          filename="package://full_amr/meshes/FL_swivel.STL" />
      </geometry>
      <material
        name="">
        <color
          rgba="0.79216 0.81961 0.93333 1" />
      </material>
    </visual>
    <collision>
      <origin
        xyz="0 0 0"
        rpy="0 0 0" />
      <geometry>
        <mesh
          filename="package://full_amr/meshes/FL_swivel.STL" />
      </geometry>
    </collision>
  </link>
  <joint
    name="FL_swivel_hinge"
    type="continuous">
    <origin
      xyz="0.000499999999999945 0.122991053569608 0.00912144406537516"
      rpy="0 0 0" />
    <parent
      link="left_pivot" />
    <child
      link="FL_swivel" />
    <axis
      xyz="0 -0.000987385793199488 0.999999512534529" />
  </joint>
  <link
    name="FL_castor">
    <inertial>
      <origin
        xyz="-2.7756E-17 -2.7756E-17 -5.5511E-17"
        rpy="0 0 0" />
      <mass
        value="0.1614" />
      <inertia
        ixx="0.00041679"
        ixy="7.9415E-07"
        ixz="7.8413E-10"
        iyy="0.00022052"
        iyz="3.1726E-12"
        izz="0.00022051" />
    </inertial>
    <visual>
      <origin
        xyz="0 0 0"
        rpy="0 0 0" />
      <geometry>
        <mesh
          filename="package://full_amr/meshes/FL_castor.STL" />
      </geometry>
      <material
        name="">
        <color
          rgba="0.79216 0.81961 0.93333 1" />
      </material>
    </visual>
    <collision>
      <origin
        xyz="0 0 0"
        rpy="0 0 0" />
      <geometry>
        <mesh
          filename="package://full_amr/meshes/FL_castor.STL" />
      </geometry>
    </collision>
  </link>
  <joint
    name="FL_castor_hinge"
    type="continuous">
    <origin
      xyz="-0.000830061024273993 -0.0419202476273774 -0.0845414326679843"
      rpy="0 0 0" />
    <parent
      link="FL_swivel" />
    <child
      link="FL_castor" />
    <axis
      xyz="0.999991815024994 0.00404596923608611 0" />
  </joint>
  <link
    name="back_pivot">
    <inertial>
      <origin
        xyz="2.40017926138347E-17 0.000116576900137055 0.0183318680820081"
        rpy="0 0 0" />
      <mass
        value="0.241012788592429" />
      <inertia
        ixx="9.580182683753E-05"
        ixy="-3.45325287521015E-20"
        ixz="-6.09125985912172E-21"
        iyy="0.000880790277251447"
        iyz="5.09984854060712E-21"
        izz="0.000957865697471465" />
    </inertial>
    <visual>
      <origin
        xyz="0 0 0"
        rpy="0 0 0" />
      <geometry>
        <mesh
          filename="package://full_amr/meshes/back_pivot.STL" />
      </geometry>
      <material
        name="">
        <color
          rgba="0.792156862745098 0.819607843137255 0.933333333333333 1" />
      </material>
    </visual>
    <collision>
      <origin
        xyz="0 0 0"
        rpy="0 0 0" />
      <geometry>
        <mesh
          filename="package://full_amr/meshes/back_pivot.STL" />
      </geometry>
    </collision>
  </link>
  <joint
    name="back_pivot_hinge"
    type="continuous">
    <origin
      xyz="0 -0.25 -0.081"
      rpy="0 0 0" />
    <parent
      link="base_link" />
    <child
      link="back_pivot" />
    <axis
      xyz="0 -1 0" />
  </joint>
  <link
    name="BR_swivel">
    <inertial>
      <origin
        xyz="-2.8681E-05 -0.015673 -0.026421"
        rpy="0 0 0" />
      <mass
        value="0.040333" />
      <inertia
        ixx="4.7854E-05"
        ixy="5.893E-09"
        ixz="-2.1799E-08"
        iyy="5.1204E-05"
        iyz="-1.0874E-05"
        izz="4.839E-05" />
    </inertial>
    <visual>
      <origin
        xyz="0 0 0"
        rpy="0 0 0" />
      <geometry>
        <mesh
          filename="package://full_amr/meshes/BR_swivel.STL" />
      </geometry>
      <material
        name="">
        <color
          rgba="0.79216 0.81961 0.93333 1" />
      </material>
    </visual>
    <collision>
      <origin
        xyz="0 0 0"
        rpy="0 0 0" />
      <geometry>
        <mesh
          filename="package://full_amr/meshes/BR_swivel.STL" />
      </geometry>
    </collision>
  </link>
  <joint
    name="BR_swivel_hinge"
    type="continuous">
    <origin
      xyz="0.160500000000001 0.000500000000000667 0.00899999999999893"
      rpy="0 0 0" />
    <parent
      link="back_pivot" />
    <child
      link="BR_swivel" />
    <axis
      xyz="0 0 1" />
  </joint>
  <link
    name="BR_castor">
    <inertial>
      <origin
        xyz="7.494E-16 2.7756E-16 -3.0531E-16"
        rpy="0 0 0" />
      <mass
        value="0.1614" />
      <inertia
        ixx="0.0004168"
        ixy="-3.8551E-07"
        ixz="-1.2959E-18"
        iyy="0.00022051"
        iyz="1.1216E-20"
        izz="0.00022051" />
    </inertial>
    <visual>
      <origin
        xyz="0 0 0"
        rpy="0 0 0" />
      <geometry>
        <mesh
          filename="package://full_amr/meshes/BR_castor.STL" />
      </geometry>
      <material
        name="">
        <color
          rgba="0.79216 0.81961 0.93333 1" />
      </material>
    </visual>
    <collision>
      <origin
        xyz="0 0 0"
        rpy="0 0 0" />
      <geometry>
        <mesh
          filename="package://full_amr/meshes/BR_castor.STL" />
      </geometry>
    </collision>
  </link>
  <joint
    name="BR_castor_hinge"
    type="continuous">
    <origin
      xyz="0.000917507259500183 -0.0420018830581295 -0.0844999999999997"
      rpy="0 0 0" />
    <parent
      link="BR_swivel" />
    <child
      link="BR_castor" />
    <axis
      xyz="-0.999998071218656 0.00196406694564723 0" />
  </joint>
  <link
    name="BL_swivel">
    <inertial>
      <origin
        xyz="-8.2362E-05 -0.015672 -0.026421"
        rpy="0 0 0" />
      <mass
        value="0.040333" />
      <inertia
        ixx="4.7854E-05"
        ixy="1.7369E-08"
        ixz="-5.9044E-08"
        iyy="5.1204E-05"
        iyz="-1.0874E-05"
        izz="4.839E-05" />
    </inertial>
    <visual>
      <origin
        xyz="0 0 0"
        rpy="0 0 0" />
      <geometry>
        <mesh
          filename="package://full_amr/meshes/BL_swivel.STL" />
      </geometry>
      <material
        name="">
        <color
          rgba="0.79216 0.81961 0.93333 1" />
      </material>
    </visual>
    <collision>
      <origin
        xyz="0 0 0"
        rpy="0 0 0" />
      <geometry>
        <mesh
          filename="package://full_amr/meshes/BL_swivel.STL" />
      </geometry>
    </collision>
  </link>
  <joint
    name="BL_swivel_hinge"
    type="continuous">
    <origin
      xyz="-0.160499999999999 0.000499999999999445 0.00900000000000113"
      rpy="0 0 0" />
    <parent
      link="back_pivot" />
    <child
      link="BL_swivel" />
    <axis
      xyz="0 0 1" />
  </joint>
  <link
    name="BL_castor">
    <inertial>
      <origin
        xyz="6.9389E-16 -6.1062E-16 0"
        rpy="0 0 0" />
      <mass
        value="0.1614" />
      <inertia
        ixx="0.00041679"
        ixy="-1.0578E-06"
        ixz="-1.2987E-18"
        iyy="0.00022052"
        iyz="3.2613E-20"
        izz="0.00022051" />
    </inertial>
    <visual>
      <origin
        xyz="0 0 0"
        rpy="0 0 0" />
      <geometry>
        <mesh
          filename="package://full_amr/meshes/BL_castor.STL" />
      </geometry>
      <material
        name="">
        <color
          rgba="0.79216 0.81961 0.93333 1" />
      </material>
    </visual>
    <collision>
      <origin
        xyz="0 0 0"
        rpy="0 0 0" />
      <geometry>
        <mesh
          filename="package://full_amr/meshes/BL_castor.STL" />
      </geometry>
    </collision>
  </link>
  <joint
    name="BL_castor_hinge"
    type="continuous">
    <origin
      xyz="-0.00122633583817874 -0.0419940007669185 -0.0845"
      rpy="0 0 0" />
    <parent
      link="BL_swivel" />
    <child
      link="BL_castor" />
    <axis
      xyz="-0.999985477648034 0.00538929429831941 0" />
  </joint>
  <link
    name="zed2">
    <inertial>
      <origin
        xyz="-0.0011152 -0.060001 4.5338E-05"
        rpy="0 0 0" />
      <mass
        value="0.15226" />
      <inertia
        ixx="0.00037235"
        ixy="2.3054E-09"
        ixz="4.7919E-08"
        iyy="2.2805E-05"
        iyz="4.8165E-10"
        izz="0.00037478" />
    </inertial>
    <visual>
      <origin
        xyz="0 0 0"
        rpy="0 0 0" />
      <geometry>
        <mesh
          filename="package://full_amr/meshes/zed2.STL" />
      </geometry>
      <material
        name="">
        <color
          rgba="0.79216 0.81961 0.93333 1" />
      </material>
    </visual>
    <collision>
      <origin
        xyz="0 0 0"
        rpy="0 0 0" />
      <geometry>
        <mesh
          filename="package://full_amr/meshes/zed2.STL" />
      </geometry>
    </collision>
  </link>
  <joint
    name="zed2_hinge"
    type="fixed">
    <origin
      xyz="-0.06 0.37395 -0.090184"
      rpy="0 0 1.5708" />
    <parent
      link="base_link" />
    <child
      link="zed2" />
    <axis
      xyz="0 0 0" />
  </joint>
  <link
    name="m2m2">
    <inertial>
      <origin
        xyz="0 8.6736E-19 -0.006"
        rpy="0 0 0" />
      <mass
        value="0.19138" />
      <inertia
        ixx="0.00012857"
        ixy="9.6296E-35"
        ixz="3.9527E-37"
        iyy="0.00012857"
        iyz="-2.3695E-36"
        izz="7.7725E-05" />
    </inertial>
    <visual>
      <origin
        xyz="0 0 0"
        rpy="0 0 0" />
      <geometry>
        <mesh
          filename="package://full_amr/meshes/m2m2.STL" />
      </geometry>
      <material
        name="">
        <color
          rgba="0.79216 0.81961 0.93333 1" />
      </material>
    </visual>
    <collision>
      <origin
        xyz="0 0 0"
        rpy="0 0 0" />
      <geometry>
        <mesh
          filename="package://full_amr/meshes/m2m2.STL" />
      </geometry>
    </collision>
  </link>
  <joint
    name="m2m2_hinge"
    type="fixed">
    <origin
      xyz="-0.005 0.3075 -0.061"
      rpy="0 0 -1.5708" />
    <parent
      link="base_link" />
    <child
      link="m2m2" />
    <axis
      xyz="0 0 0" />
  </joint>
  <link
    name="imu">
    <inertial>
      <origin
        xyz="0 0 0"
        rpy="0 0 0" />
      <mass
        value="0" />
      <inertia
        ixx="0"
        ixy="0"
        ixz="0"
        iyy="0"
        iyz="0"
        izz="0" />
    </inertial>
    <visual>
      <origin
        xyz="0 0 0"
        rpy="0 0 0" />
      <geometry>
        <mesh
          filename="package://full_amr/meshes/imu.STL" />
      </geometry>
      <material
        name="">
        <color
          rgba="1 1 1 1" />
      </material>
    </visual>
    <collision>
      <origin
        xyz="0 0 0"
        rpy="0 0 0" />
      <geometry>
        <mesh
          filename="package://full_amr/meshes/imu.STL" />
      </geometry>
    </collision>
  </link>
  <joint
    name="imu_hinge"
    type="fixed">
    <origin
      xyz="0 0.2275 -0.0980997999999998"
      rpy="3.14159265358979 0 0" />
    <parent
      link="base_link" />
    <child
      link="imu" />
    <axis
      xyz="0 0 0" />
  </joint>
</robot>