<?xml version="1.0" encoding="utf-8"?>
<!-- This URDF was automatically created by SolidWorks to URDF Exporter! Originally created by Stephen Brawner (brawner@gmail.com) 
     Commit Version: 1.6.0-4-g7f85cfe  Build Version: 1.6.7995.38578
     For more information, please see http://wiki.ros.org/sw_urdf_exporter -->
<robot
  name="full_amr">
  <link
    name="base_link">
    <inertial>
      <origin
        xyz="4.3964E-07 0.067797 -0.06095"
        rpy="0 0 0" />
      <mass
        value="3.8632" />
      <inertia
        ixx="0.066007"
        ixy="2.416E-08"
        ixz="-3.2997E-08"
        iyy="0.076685"
        iyz="1.2597E-07"
        izz="0.1421" />
    </inertial>
    <visual>
      <origin
        xyz="0 0 0"
        rpy="0 0 0" />
      <geometry>
        <mesh
          filename="package://full_amr/meshes/base_link.STL" />
      </geometry>
      <material
        name="">
        <color
          rgba="0 0 0 1" />
      </material>
    </visual>
    <collision>
      <origin
        xyz="0 0 0"
        rpy="0 0 0" />
      <geometry>
        <mesh
          filename="package://full_amr/meshes/base_link.STL" />
      </geometry>
    </collision>
  </link>
  <link
    name="right_pivot">
    <inertial>
      <origin
        xyz="6.7225E-05 0.042261 0.014296"
        rpy="0 0 0" />
      <mass
        value="0.17398" />
      <inertia
        ixx="0.00035672"
        ixy="8.0021E-10"
        ixz="-7.7696E-08"
        iyy="6.8709E-05"
        iyz="3.4167E-06"
        izz="0.00038711" />
    </inertial>
    <visual>
      <origin
        xyz="0 0 0"
        rpy="0 0 0" />
      <geometry>
        <mesh
          filename="package://full_amr/meshes/right_pivot.STL" />
      </geometry>
      <material
        name="">
        <color
          rgba="0 0 0 1" />
      </material>
    </visual>
    <collision>
      <origin
        xyz="0 0 0"
        rpy="0 0 0" />
      <geometry>
        <mesh
          filename="package://full_amr/meshes/right_pivot.STL" />
      </geometry>
    </collision>
  </link>
  <joint
    name="right_pivot_hinge"
    type="continuous">
    <origin
      xyz="0.162500000000008 0.127500000000012 -0.0809999999999999"
      rpy="0 0 0" />
    <parent
      link="base_link" />
    <child
      link="right_pivot" />
    <axis
      xyz="1 0 0" />
  </joint>
  <link
    name="right_wheel">
    <inertial>
      <origin
        xyz="8.82920752592452E-08 -1.86536985857799E-08 -1.07619964538064E-05"
        rpy="0 0 0" />
      <mass
        value="0.671865219229546" />
      <inertia
        ixx="0.00152382831042098"
        ixy="-2.99658197542106E-09"
        ixz="-7.08391619242621E-10"
        iyy="0.00152383788550933"
        iyz="3.46009207170634E-10"
        izz="0.00291423163667508" />
    </inertial>
    <visual>
      <origin
        xyz="0 0 0"
        rpy="0 0 0" />
      <geometry>
        <mesh
          filename="package://full_amr/meshes/right_wheel.STL" />
      </geometry>
      <material
        name="">
        <color
          rgba="0.792156862745098 0.819607843137255 0.933333333333333 1" />
      </material>
    </visual>
    <collision>
      <origin
        xyz="0 0 0"
        rpy="0 0 0" />
      <geometry>
        <mesh
          filename="package://full_amr/meshes/right_wheel.STL" />
      </geometry>
    </collision>
  </link>
  <joint
    name="right_wheel_hinge"
    type="continuous">
    <origin
      xyz="0.060600000000002 -0.127825510601864 -0.0494161040489112"
      rpy="1.5707963267949 0 1.5707963267949" />
    <parent
      link="right_pivot" />
    <child
      link="right_wheel" />
    <axis
      xyz="0 0 -1" />
  </joint>
  <link
    name="FR_swivel">
    <inertial>
      <origin
        xyz="2.10136369047098E-06 -0.0158449037086422 -0.0263178294256963"
        rpy="0 0 0" />
      <mass
        value="0.0403331792084209" />
      <inertia
        ixx="4.785449627293E-05"
        ixy="-6.90281179955184E-10"
        ixz="-4.45519404587136E-10"
        iyy="5.10623960568999E-05"
        iyz="-1.08916975241884E-05"
        izz="4.85318020084124E-05" />
    </inertial>
    <visual>
      <origin
        xyz="0 0 0"
        rpy="0 0 0" />
      <geometry>
        <mesh
          filename="package://full_amr/meshes/FR_swivel.STL" />
      </geometry>
      <material
        name="">
        <color
          rgba="0.792156862745098 0.819607843137255 0.933333333333333 1" />
      </material>
    </visual>
    <collision>
      <origin
        xyz="0 0 0"
        rpy="0 0 0" />
      <geometry>
        <mesh
          filename="package://full_amr/meshes/FR_swivel.STL" />
      </geometry>
    </collision>
  </link>
  <joint
    name="FR_swivel_hinge"
    type="continuous">
    <origin
      xyz="0.000499999999999584 0.123056163560861 0.00819637783921516"
      rpy="0 0 0" />
    <parent
      link="right_pivot" />
    <child
      link="FR_swivel" />
    <axis
      xyz="0 0.00653195251969943 0.999978666570583" />
  </joint>
  <link
    name="FR_castor">
    <inertial>
      <origin
        xyz="2.16493489801906E-14 -1.02695629777827E-15 1.89293025698589E-14"
        rpy="0 0 0" />
      <mass
        value="0.16139609361482" />
      <inertia
        ixx="0.000416796707486866"
        ixy="2.73308301420083E-18"
        ixz="-6.94855921025798E-19"
        iyy="0.000220513659227019"
        iyz="4.47350390856318E-20"
        izz="0.000220513659227019" />
    </inertial>
    <visual>
      <origin
        xyz="0 0 0"
        rpy="0 0 0" />
      <geometry>
        <mesh
          filename="package://full_amr/meshes/FR_castor.STL" />
      </geometry>
      <material
        name="">
        <color
          rgba="0.792156862745098 0.819607843137255 0.933333333333333 1" />
      </material>
    </visual>
    <collision>
      <origin
        xyz="0 0 0"
        rpy="0 0 0" />
      <geometry>
        <mesh
          filename="package://full_amr/meshes/FR_castor.STL" />
      </geometry>
    </collision>
  </link>
  <joint
    name="FR_castor_hinge"
    type="continuous">
    <origin
      xyz="0.00099999999997849 -0.0425510539838774 -0.0842238553194065"
      rpy="0 0 0" />
    <parent
      link="FR_swivel" />
    <child
      link="FR_castor" />
    <axis
      xyz="1 0 0" />
  </joint>
  <link
    name="left_pivot">
    <inertial>
      <origin
        xyz="6.7225E-05 0.042152 0.014614"
        rpy="0 0 0" />
      <mass
        value="0.17398" />
      <inertia
        ixx="0.00035672"
        ixy="1.3844E-09"
        ixz="-7.7688E-08"
        iyy="6.8675E-05"
        iyz="1.0222E-06"
        izz="0.00038715" />
    </inertial>
    <visual>
      <origin
        xyz="0 0 0"
        rpy="0 0 0" />
      <geometry>
        <mesh
          filename="package://full_amr/meshes/left_pivot.STL" />
      </geometry>
      <material
        name="">
        <color
          rgba="0 0 0 1" />
      </material>
    </visual>
    <collision>
      <origin
        xyz="0 0 0"
        rpy="0 0 0" />
      <geometry>
        <mesh
          filename="package://full_amr/meshes/left_pivot.STL" />
      </geometry>
    </collision>
  </link>
  <joint
    name="left_pivot_hinge"
    type="continuous">
    <origin
      xyz="-0.162500000000001 0.12749999999999 -0.081"
      rpy="0 0 0" />
    <parent
      link="base_link" />
    <child
      link="left_pivot" />
    <axis
      xyz="1 0 0" />
  </joint>
  <link
    name="left_wheel">
    <inertial>
      <origin
        xyz="5.10511360407584E-08 7.44125832301059E-08 -1.07619964537509E-05"
        rpy="0 0 0" />
      <mass
        value="0.671865219229547" />
      <inertia
        ixx="0.00152383860116951"
        ixy="-1.27075746565576E-09"
        ixz="-5.90967111167551E-10"
        iyy="0.00152382759476079"
        iyz="-5.21822709907927E-10"
        izz="0.00291423163667508" />
    </inertial>
    <visual>
      <origin
        xyz="0 0 0"
        rpy="0 0 0" />
      <geometry>
        <mesh
          filename="package://full_amr/meshes/left_wheel.STL" />
      </geometry>
      <material
        name="">
        <color
          rgba="0.792156862745098 0.819607843137255 0.933333333333333 1" />
      </material>
    </visual>
    <collision>
      <origin
        xyz="0 0 0"
        rpy="0 0 0" />
      <geometry>
        <mesh
          filename="package://full_amr/meshes/left_wheel.STL" />
      </geometry>
    </collision>
  </link>
  <joint
    name="left_wheel_hinge"
    type="continuous">
    <origin
      xyz="-0.0606000000000003 -0.127450321712043 -0.050375867193494"
      rpy="3.14159265358979 -1.5707963267949 0" />
    <parent
      link="left_pivot" />
    <child
      link="left_wheel" />
    <axis
      xyz="0 0 -1" />
  </joint>
  <link
    name="FL_swivel">
    <inertial>
      <origin
        xyz="6.5511778461258E-05 -0.0156463149501383 -0.0264362233956825"
        rpy="0 0 0" />
      <mass
        value="0.0403332363730702" />
      <inertia
        ixx="4.78543933221479E-05"
        ixy="-1.42826551762756E-08"
        ixz="4.35430090190856E-08"
        iyy="5.12258920158362E-05"
        iyz="-1.08712913722346E-05"
        izz="4.83681025928456E-05" />
    </inertial>
    <visual>
      <origin
        xyz="0 0 0"
        rpy="0 0 0" />
      <geometry>
        <mesh
          filename="package://full_amr/meshes/FL_swivel.STL" />
      </geometry>
      <material
        name="">
        <color
          rgba="0.792156862745098 0.819607843137255 0.933333333333333 1" />
      </material>
    </visual>
    <collision>
      <origin
        xyz="0 0 0"
        rpy="0 0 0" />
      <geometry>
        <mesh
          filename="package://full_amr/meshes/FL_swivel.STL" />
      </geometry>
    </collision>
  </link>
  <joint
    name="FL_swivel_hinge"
    type="continuous">
    <origin
      xyz="0.000499999999999945 0.122991053569608 0.00912144406537516"
      rpy="0 0 0" />
    <parent
      link="left_pivot" />
    <child
      link="FL_swivel" />
    <axis
      xyz="0 -0.000987385793199488 0.999999512534529" />
  </joint>
  <link
    name="FL_castor">
    <inertial>
      <origin
        xyz="-2.77555756156289E-17 -2.77555756156289E-17 -5.55111512312578E-17"
        rpy="0 0 0" />
      <mass
        value="0.161396093614819" />
      <inertia
        ixx="0.000416793494356327"
        ixy="7.94148674684207E-07"
        ixz="7.84131501411023E-10"
        iyy="0.000220516872354425"
        iyz="3.17259789254566E-12"
        izz="0.000220513659230152" />
    </inertial>
    <visual>
      <origin
        xyz="0 0 0"
        rpy="0 0 0" />
      <geometry>
        <mesh
          filename="package://full_amr/meshes/FL_castor.STL" />
      </geometry>
      <material
        name="">
        <color
          rgba="0.792156862745098 0.819607843137255 0.933333333333333 1" />
      </material>
    </visual>
    <collision>
      <origin
        xyz="0 0 0"
        rpy="0 0 0" />
      <geometry>
        <mesh
          filename="package://full_amr/meshes/FL_castor.STL" />
      </geometry>
    </collision>
  </link>
  <joint
    name="FL_castor_hinge"
    type="continuous">
    <origin
      xyz="-0.000830061024273993 -0.0419202476273774 -0.0845414326679843"
      rpy="0 0 0" />
    <parent
      link="FL_swivel" />
    <child
      link="FL_castor" />
    <axis
      xyz="0.999991815024994 0.00404596923608611 0" />
  </joint>
  <link
    name="back_pivot">
    <inertial>
      <origin
        xyz="1.3572E-16 0.00011658 0.018332"
        rpy="0 0 0" />
      <mass
        value="0.24101" />
      <inertia
        ixx="9.5802E-05"
        ixy="-3.9655E-20"
        ixz="-1.3949E-21"
        iyy="0.00088079"
        iyz="3.0936E-21"
        izz="0.00095787" />
    </inertial>
    <visual>
      <origin
        xyz="0 0 0"
        rpy="0 0 0" />
      <geometry>
        <mesh
          filename="package://full_amr/meshes/back_pivot.STL" />
      </geometry>
      <material
        name="">
        <color
          rgba="0 0 0 1" />
      </material>
    </visual>
    <collision>
      <origin
        xyz="0 0 0"
        rpy="0 0 0" />
      <geometry>
        <mesh
          filename="package://full_amr/meshes/back_pivot.STL" />
      </geometry>
    </collision>
  </link>
  <joint
    name="back_pivot_hinge"
    type="continuous">
    <origin
      xyz="0 -0.24999999999999 -0.0810000000000002"
      rpy="0 0 0" />
    <parent
      link="base_link" />
    <child
      link="back_pivot" />
    <axis
      xyz="0 -1 0" />
  </joint>
  <link
    name="BR_swivel">
    <inertial>
      <origin
        xyz="-2.86806979955812E-05 -0.0156725402272886 -0.0264207636386581"
        rpy="0 0 0" />
      <mass
        value="0.0403332273268806" />
      <inertia
        ixx="4.78543953407379E-05"
        ixy="5.8929654746271E-09"
        ixz="-2.17988033710859E-08"
        iyy="5.12044981326952E-05"
        iyz="-1.08741782741284E-05"
        izz="4.838958990946E-05" />
    </inertial>
    <visual>
      <origin
        xyz="0 0 0"
        rpy="0 0 0" />
      <geometry>
        <mesh
          filename="package://full_amr/meshes/BR_swivel.STL" />
      </geometry>
      <material
        name="">
        <color
          rgba="0.792156862745098 0.819607843137255 0.933333333333333 1" />
      </material>
    </visual>
    <collision>
      <origin
        xyz="0 0 0"
        rpy="0 0 0" />
      <geometry>
        <mesh
          filename="package://full_amr/meshes/BR_swivel.STL" />
      </geometry>
    </collision>
  </link>
  <joint
    name="BR_swivel_hinge"
    type="continuous">
    <origin
      xyz="0.160500000000001 0.000500000000000667 0.00899999999999893"
      rpy="0 0 0" />
    <parent
      link="back_pivot" />
    <child
      link="BR_swivel" />
    <axis
      xyz="0 0 1" />
  </joint>
  <link
    name="BR_castor">
    <inertial>
      <origin
        xyz="7.49400541621981E-16 2.77555756156289E-16 -2.77555756156289E-16"
        rpy="0 0 0" />
      <mass
        value="0.16139609361482" />
      <inertia
        ixx="0.000416795950313433"
        ixy="-3.85512303507541E-07"
        ixz="-1.31224261119139E-18"
        iyy="0.000220514416400453"
        iyz="-1.72229331427263E-20"
        izz="0.000220513659227019" />
    </inertial>
    <visual>
      <origin
        xyz="0 0 0"
        rpy="0 0 0" />
      <geometry>
        <mesh
          filename="package://full_amr/meshes/BR_castor.STL" />
      </geometry>
      <material
        name="">
        <color
          rgba="0.792156862745098 0.819607843137255 0.933333333333333 1" />
      </material>
    </visual>
    <collision>
      <origin
        xyz="0 0 0"
        rpy="0 0 0" />
      <geometry>
        <mesh
          filename="package://full_amr/meshes/BR_castor.STL" />
      </geometry>
    </collision>
  </link>
  <joint
    name="BR_castor_hinge"
    type="continuous">
    <origin
      xyz="0.000917507259500183 -0.0420018830581295 -0.0844999999999997"
      rpy="0 0 0" />
    <parent
      link="BR_swivel" />
    <child
      link="BR_castor" />
    <axis
      xyz="-0.999998071218656 0.00196406694564723 0" />
  </joint>
  <link
    name="BL_swivel">
    <inertial>
      <origin
        xyz="-8.23621583788681E-05 -0.0156723375221494 -0.0264207621674671"
        rpy="0 0 0" />
      <mass
        value="0.040333232832404" />
      <inertia
        ixx="4.7854441195365E-05"
        ixy="1.73687216368046E-08"
        ixz="-5.90443392248629E-08"
        iyy="5.12044011536028E-05"
        iyz="-1.08740264445735E-05"
        izz="4.83895789718872E-05" />
    </inertial>
    <visual>
      <origin
        xyz="0 0 0"
        rpy="0 0 0" />
      <geometry>
        <mesh
          filename="package://full_amr/meshes/BL_swivel.STL" />
      </geometry>
      <material
        name="">
        <color
          rgba="0.792156862745098 0.819607843137255 0.933333333333333 1" />
      </material>
    </visual>
    <collision>
      <origin
        xyz="0 0 0"
        rpy="0 0 0" />
      <geometry>
        <mesh
          filename="package://full_amr/meshes/BL_swivel.STL" />
      </geometry>
    </collision>
  </link>
  <joint
    name="BL_swivel_hinge"
    type="continuous">
    <origin
      xyz="-0.160499999999999 0.000499999999999445 0.00900000000000113"
      rpy="0 0 0" />
    <parent
      link="back_pivot" />
    <child
      link="BL_swivel" />
    <axis
      xyz="0 0 1" />
  </joint>
  <link
    name="BL_castor">
    <inertial>
      <origin
        xyz="6.93889390390723E-16 -6.66133814775094E-16 -2.77555756156289E-17"
        rpy="0 0 0" />
      <mass
        value="0.16139609361482" />
      <inertia
        ixx="0.000416791006545238"
        ixy="-1.05781175070598E-06"
        ixz="-1.31515100667501E-18"
        iyy="0.000220519360168647"
        iyz="-2.7890663951698E-20"
        izz="0.000220513659227019" />
    </inertial>
    <visual>
      <origin
        xyz="0 0 0"
        rpy="0 0 0" />
      <geometry>
        <mesh
          filename="package://full_amr/meshes/BL_castor.STL" />
      </geometry>
      <material
        name="">
        <color
          rgba="0.792156862745098 0.819607843137255 0.933333333333333 1" />
      </material>
    </visual>
    <collision>
      <origin
        xyz="0 0 0"
        rpy="0 0 0" />
      <geometry>
        <mesh
          filename="package://full_amr/meshes/BL_castor.STL" />
      </geometry>
    </collision>
  </link>
  <joint
    name="BL_castor_hinge"
    type="continuous">
    <origin
      xyz="-0.00122633583817874 -0.0419940007669185 -0.0845"
      rpy="0 0 0" />
    <parent
      link="BL_swivel" />
    <child
      link="BL_castor" />
    <axis
      xyz="-0.999985477648034 0.00538929429831941 0" />
  </joint>
</robot>