<?xml version="1.0" encoding="utf-8"?>
<!-- This URDF was automatically created by SolidWorks to URDF Exporter! Originally created by Stephen Brawner (brawner@gmail.com) 
     Commit Version: 1.6.0-4-g7f85cfe  Build Version: 1.6.7995.38578
     For more information, please see http://wiki.ros.org/sw_urdf_exporter -->
<robot
  name="basic_amr">
  <link
    name="base_link">
    <inertial>
      <origin
        xyz="5.6354E-06 0.058561 0.070029"
        rpy="0 0 0" />
      <mass
        value="4.4522" />
      <inertia
        ixx="0.066817"
        ixy="2.6775E-08"
        ixz="-1.8838E-07"
        iyy="0.077704"
        iyz="2.7993E-06"
        izz="0.14383" />
    </inertial>
    <visual>
      <origin
        xyz="0 0 0"
        rpy="0 0 0" />
      <geometry>
        <mesh
          filename="package://basic_amr/meshes/base_link.STL" />
      </geometry>
      <material
        name="">
        <color
          rgba="0.79216 0.81961 0.93333 1" />
      </material>
    </visual>
    <collision>
      <origin
        xyz="0 0 0"
        rpy="0 0 0" />
      <geometry>
        <mesh
          filename="package://basic_amr/meshes/base_link.STL" />
      </geometry>
    </collision>
  </link>
  <link
    name="left_wheel">
    <inertial>
      <origin
        xyz="5.10511359843426E-08 -7.44125832365908E-08 1.07619964537509E-05"
        rpy="0 0 0" />
      <mass
        value="0.671865219229546" />
      <inertia
        ixx="0.00152383860116951"
        ixy="1.27075746565495E-09"
        ixz="5.90967105716134E-10"
        iyy="0.00152382759476079"
        iyz="-5.21822713916575E-10"
        izz="0.00291423163667508" />
    </inertial>
    <visual>
      <origin
        xyz="0 0 0"
        rpy="0 0 0" />
      <geometry>
        <mesh
          filename="package://basic_amr/meshes/left_wheel.STL" />
      </geometry>
      <material
        name="">
        <color
          rgba="0.792156862745098 0.819607843137255 0.933333333333333 1" />
      </material>
    </visual>
    <collision>
      <origin
        xyz="0 0 0"
        rpy="0 0 0" />
      <geometry>
        <mesh
          filename="package://basic_amr/meshes/left_wheel.STL" />
      </geometry>
    </collision>
  </link>
  <joint
    name="left_wheel_hinge"
    type="continuous">
    <origin
      xyz="-0.2231 0 0.00025"
      rpy="1.5708 0 1.5708" />
    <parent
      link="base_link" />
    <child
      link="left_wheel" />
    <axis
      xyz="0 0 1" />
  </joint>
  <link
    name="right_wheel">
    <inertial>
      <origin
        xyz="-8.41754692941766E-08 3.2526011111637E-08 -1.07619964537509E-05"
        rpy="0 0 0" />
      <mass
        value="0.671865219229547" />
      <inertia
        ixx="0.0015238276094369"
        ixy="-1.33271918232025E-09"
        ixz="6.43980179874417E-10"
        iyy="0.0015238385864934"
        iyz="-4.54786339413511E-10"
        izz="0.00291423163667508" />
    </inertial>
    <visual>
      <origin
        xyz="0 0 0"
        rpy="0 0 0" />
      <geometry>
        <mesh
          filename="package://basic_amr/meshes/right_wheel.STL" />
      </geometry>
      <material
        name="">
        <color
          rgba="0.792156862745098 0.819607843137255 0.933333333333333 1" />
      </material>
    </visual>
    <collision>
      <origin
        xyz="0 0 0"
        rpy="0 0 0" />
      <geometry>
        <mesh
          filename="package://basic_amr/meshes/right_wheel.STL" />
      </geometry>
    </collision>
  </link>
  <joint
    name="right_wheel_hinge"
    type="continuous">
    <origin
      xyz="0.2231 0 0.00025"
      rpy="1.5708 0 1.5708" />
    <parent
      link="base_link" />
    <child
      link="right_wheel" />
    <axis
      xyz="0 0 -1" />
  </joint>
  <link
    name="castor_FL_swivel">
    <inertial>
      <origin
        xyz="2.10123437094367E-06 -0.0156725676431652 -0.0264207637961363"
        rpy="0 0 0" />
      <mass
        value="0.0403332267042345" />
      <inertia
        ixx="4.78543883362956E-05"
        ixy="-6.87011071731824E-10"
        ixz="-4.41251168380599E-10"
        iyy="5.120451005742E-05"
        iyz="-1.08742014136652E-05"
        izz="4.83895908673668E-05" />
    </inertial>
    <visual>
      <origin
        xyz="0 0 0"
        rpy="0 0 0" />
      <geometry>
        <mesh
          filename="package://basic_amr/meshes/castor_FL_swivel.STL" />
      </geometry>
      <material
        name="">
        <color
          rgba="0.792156862745098 0.819607843137255 0.933333333333333 1" />
      </material>
    </visual>
    <collision>
      <origin
        xyz="0 0 0"
        rpy="0 0 0" />
      <geometry>
        <mesh
          filename="package://basic_amr/meshes/castor_FL_swivel.STL" />
      </geometry>
    </collision>
  </link>
  <joint
    name="castor_FL_swivel_hinge"
    type="continuous">
    <origin
      xyz="-0.162 0.2505 0.0595"
      rpy="0 0 -0.0016249" />
    <parent
      link="base_link" />
    <child
      link="castor_FL_swivel" />
    <axis
      xyz="0 0 1" />
  </joint>
  <link
    name="castor_FL_wheel">
    <inertial>
      <origin
        xyz="-2.77555756156289E-17 0 5.55111512312578E-17"
        rpy="0 0 0" />
      <mass
        value="0.16139609361482" />
      <inertia
        ixx="0.000220514177487319"
        ixy="1.66946145790432E-20"
        ixz="-3.18944262751873E-07"
        iyy="0.00022051365922702"
        iyz="-5.89663587417203E-19"
        izz="0.000416796189226567" />
    </inertial>
    <visual>
      <origin
        xyz="0 0 0"
        rpy="0 0 0" />
      <geometry>
        <mesh
          filename="package://basic_amr/meshes/castor_FL_wheel.STL" />
      </geometry>
      <material
        name="">
        <color
          rgba="0.792156862745098 0.819607843137255 0.933333333333333 1" />
      </material>
    </visual>
    <collision>
      <origin
        xyz="0 0 0"
        rpy="0 0 0" />
      <geometry>
        <mesh
          filename="package://basic_amr/meshes/castor_FL_wheel.STL" />
      </geometry>
    </collision>
  </link>
  <joint
    name="castor_FL_wheel_hinge"
    type="continuous">
    <origin
      xyz="-0.001 -0.042 -0.0845"
      rpy="1.5708 0 1.5724" />
    <parent
      link="castor_FL_swivel" />
    <child
      link="castor_FL_wheel" />
    <axis
      xyz="0 0 -1" />
  </joint>
  <link
    name="castor_FR_swivel">
    <inertial>
      <origin
        xyz="2.10104722978E-06 -0.0156725739371237 -0.0264207645470235"
        rpy="0 0 0" />
      <mass
        value="0.0403332237188927" />
      <inertia
        ixx="4.78544037601188E-05"
        ixy="-6.87574813086455E-10"
        ixz="-4.41750017853089E-10"
        iyy="5.1204518198407E-05"
        iyz="-1.08742076360189E-05"
        izz="4.83895954535566E-05" />
    </inertial>
    <visual>
      <origin
        xyz="0 0 0"
        rpy="0 0 0" />
      <geometry>
        <mesh
          filename="package://basic_amr/meshes/castor_FR_swivel.STL" />
      </geometry>
      <material
        name="">
        <color
          rgba="0.792156862745098 0.819607843137255 0.933333333333333 1" />
      </material>
    </visual>
    <collision>
      <origin
        xyz="0 0 0"
        rpy="0 0 0" />
      <geometry>
        <mesh
          filename="package://basic_amr/meshes/castor_FR_swivel.STL" />
      </geometry>
    </collision>
  </link>
  <joint
    name="castor_FR_swivel_hinge"
    type="continuous">
    <origin
      xyz="0.163 0.2505 0.0595"
      rpy="0 0 0" />
    <parent
      link="base_link" />
    <child
      link="castor_FR_swivel" />
    <axis
      xyz="0 0 1" />
  </joint>
  <link
    name="castor_FR_wheel">
    <inertial>
      <origin
        xyz="-2.77555756156289E-17 3.46944695195361E-18 -5.55111512312578E-17"
        rpy="0 0 0" />
      <mass
        value="0.16139609361482" />
      <inertia
        ixx="0.00022051365922702"
        ixy="-1.41172157876631E-22"
        ixz="-6.89107063158536E-19"
        iyy="0.00022051365922702"
        iyz="2.55805140965836E-19"
        izz="0.000416796707486866" />
    </inertial>
    <visual>
      <origin
        xyz="0 0 0"
        rpy="0 0 0" />
      <geometry>
        <mesh
          filename="package://basic_amr/meshes/castor_FR_wheel.STL" />
      </geometry>
      <material
        name="">
        <color
          rgba="0.792156862745098 0.819607843137255 0.933333333333333 1" />
      </material>
    </visual>
    <collision>
      <origin
        xyz="0 0 0"
        rpy="0 0 0" />
      <geometry>
        <mesh
          filename="package://basic_amr/meshes/castor_FR_wheel.STL" />
      </geometry>
    </collision>
  </link>
  <joint
    name="castor_FR_wheel_hinge"
    type="continuous">
    <origin
      xyz="0.001 -0.042 -0.0845"
      rpy="1.5708 0 1.5708" />
    <parent
      link="castor_FR_swivel" />
    <child
      link="castor_FR_wheel" />
    <axis
      xyz="0 0 1" />
  </joint>
  <link
    name="castor_BL_swivel">
    <inertial>
      <origin
        xyz="2.10095743996552E-06 -0.0156725645593307 -0.0264207635526482"
        rpy="0 0 0" />
      <mass
        value="0.0403332282795378" />
      <inertia
        ixx="4.78543808653988E-05"
        ixy="-6.86722367262755E-10"
        ixz="-4.40971896740577E-10"
        iyy="5.12045060578292E-05"
        iyz="-1.08741983604408E-05"
        izz="4.83895886990048E-05" />
    </inertial>
    <visual>
      <origin
        xyz="0 0 0"
        rpy="0 0 0" />
      <geometry>
        <mesh
          filename="package://basic_amr/meshes/castor_BL_swivel.STL" />
      </geometry>
      <material
        name="">
        <color
          rgba="0.792156862745098 0.819607843137255 0.933333333333333 1" />
      </material>
    </visual>
    <collision>
      <origin
        xyz="0 0 0"
        rpy="0 0 0" />
      <geometry>
        <mesh
          filename="package://basic_amr/meshes/castor_BL_swivel.STL" />
      </geometry>
    </collision>
  </link>
  <joint
    name="castor_BL_swivel_hinge"
    type="continuous">
    <origin
      xyz="-0.1605 -0.2495 0.0595"
      rpy="0 0 0.0024111" />
    <parent
      link="base_link" />
    <child
      link="castor_BL_swivel" />
    <axis
      xyz="0 0 1" />
  </joint>
  <link
    name="castor_BL_wheel">
    <inertial>
      <origin
        xyz="0 -6.93889390390723E-18 2.77555756156289E-17"
        rpy="0 0 0" />
      <mass
        value="0.16139609361482" />
      <inertia
        ixx="0.000220514800254536"
        ixy="2.01934287089658E-20"
        ixz="4.73247353082534E-07"
        iyy="0.00022051365922702"
        iyz="-6.82980996022302E-19"
        izz="0.000416795566459349" />
    </inertial>
    <visual>
      <origin
        xyz="0 0 0"
        rpy="0 0 0" />
      <geometry>
        <mesh
          filename="package://basic_amr/meshes/castor_BL_wheel.STL" />
      </geometry>
      <material
        name="">
        <color
          rgba="0.792156862745098 0.819607843137255 0.933333333333333 1" />
      </material>
    </visual>
    <collision>
      <origin
        xyz="0 0 0"
        rpy="0 0 0" />
      <geometry>
        <mesh
          filename="package://basic_amr/meshes/castor_BL_wheel.STL" />
      </geometry>
    </collision>
  </link>
  <joint
    name="castor_BL_wheel_hinge"
    type="continuous">
    <origin
      xyz="-0.001 -0.042 -0.0845"
      rpy="1.5708 0 1.5684" />
    <parent
      link="castor_BL_swivel" />
    <child
      link="castor_BL_wheel" />
    <axis
      xyz="0 0 -1" />
  </joint>
  <link
    name="castor_BR_swivel">
    <inertial>
      <origin
        xyz="2.10049600379847E-06 -0.0156725322993151 -0.0264207602836178"
        rpy="0 0 0" />
      <mass
        value="0.0403332436496892" />
      <inertia
        ixx="4.78542990494955E-05"
        ixy="-6.83952454519116E-10"
        ixz="-4.38257061590346E-10"
        iyy="5.12044631818848E-05"
        iyz="-1.08741654398376E-05"
        izz="4.83895637325329E-05" />
    </inertial>
    <visual>
      <origin
        xyz="0 0 0"
        rpy="0 0 0" />
      <geometry>
        <mesh
          filename="package://basic_amr/meshes/castor_BR_swivel.STL" />
      </geometry>
      <material
        name="">
        <color
          rgba="0.792156862745098 0.819607843137255 0.933333333333333 1" />
      </material>
    </visual>
    <collision>
      <origin
        xyz="0 0 0"
        rpy="0 0 0" />
      <geometry>
        <mesh
          filename="package://basic_amr/meshes/castor_BR_swivel.STL" />
      </geometry>
    </collision>
  </link>
  <joint
    name="castor_BR_swivel_hinge"
    type="continuous">
    <origin
      xyz="0.1605 -0.2495 0.0595"
      rpy="0 0 0.010886" />
    <parent
      link="base_link" />
    <child
      link="castor_BR_swivel" />
    <axis
      xyz="0 0 1" />
  </joint>
  <link
    name="castor_BR_wheel">
    <inertial>
      <origin
        xyz="5.55111512312578E-17 -1.04083408558608E-17 -2.77555756156289E-17"
        rpy="0 0 0" />
      <mass
        value="0.161396093614819" />
      <inertia
        ixx="0.000220536920136407"
        ixy="-2.49573167323756E-20"
        ixz="2.13662844924712E-06"
        iyy="0.000220513659227019"
        iyz="2.3211830526184E-19"
        izz="0.000416773446577477" />
    </inertial>
    <visual>
      <origin
        xyz="0 0 0"
        rpy="0 0 0" />
      <geometry>
        <mesh
          filename="package://basic_amr/meshes/castor_BR_wheel.STL" />
      </geometry>
      <material
        name="">
        <color
          rgba="0.792156862745098 0.819607843137255 0.933333333333333 1" />
      </material>
    </visual>
    <collision>
      <origin
        xyz="0 0 0"
        rpy="0 0 0" />
      <geometry>
        <mesh
          filename="package://basic_amr/meshes/castor_BR_wheel.STL" />
      </geometry>
    </collision>
  </link>
  <joint
    name="castor_BR_wheel_hinge"
    type="continuous">
    <origin
      xyz="0.001 -0.042 -0.0845"
      rpy="1.5708 0 1.5599" />
    <parent
      link="castor_BR_swivel" />
    <child
      link="castor_BR_wheel" />
    <axis
      xyz="0 0 1" />
  </joint>
</robot>