<?xml version="1.0" encoding="utf-8"?>
<!-- This URDF was automatically created by SolidWorks to URDF Exporter! Originally created by Stephen Brawner (brawner@gmail.com) 
     Commit Version: 1.6.0-4-g7f85cfe  Build Version: 1.6.7995.38578
     For more information, please see http://wiki.ros.org/sw_urdf_exporter -->
<robot
  name="amr_urdf">
  <link
    name="base_link">
    <inertial>
      <origin
        xyz="0.0666153548166185 0.075795430260861 8.74123066818555E-07"
        rpy="0 0 0" />
      <mass
        value="3.93344073192102" />
      <inertia
        ixx="0.0767105445771446"
        ixy="2.00443327981639E-07"
        ixz="2.41600659519042E-08"
        iyy="0.142107015392246"
        iyz="-7.02349786316741E-08"
        izz="0.0660340529826635" />
    </inertial>
    <visual>
      <origin
        xyz="0 0 0"
        rpy="0 0 0" />
      <geometry>
        <mesh
          filename="package://amr_urdf/meshes/base_link.STL" />
      </geometry>
      <material
        name="">
        <color
          rgba="0.752941176470588 0.752941176470588 0.752941176470588 1" />
      </material>
    </visual>
    <collision>
      <origin
        xyz="0 0 0"
        rpy="0 0 0" />
      <geometry>
        <mesh
          filename="package://amr_urdf/meshes/base_link.STL" />
      </geometry>
    </collision>
  </link>
  <link
    name="link 1">
    <inertial>
      <origin
        xyz="-0.0502075819106562 -0.0427535438769911 -0.032603510839011"
        rpy="0 0 0" />
      <mass
        value="1.17798083990605" />
      <inertia
        ixx="0.00191275651198906"
        ixy="-3.44377502248107E-05"
        ixz="-2.56866063285056E-07"
        iyy="0.00223387023154719"
        iyz="6.51400313643542E-08"
        izz="0.00376775616389511" />
    </inertial>
    <visual>
      <origin
        xyz="0 0 0"
        rpy="0 0 0" />
      <geometry>
        <mesh
          filename="package://amr_urdf/meshes/link 1.STL" />
      </geometry>
      <material
        name="">
        <color
          rgba="0.752941176470588 0.752941176470588 0.752941176470588 1" />
      </material>
    </visual>
    <collision>
      <origin
        xyz="0 0 0"
        rpy="0 0 0" />
      <geometry>
        <mesh
          filename="package://amr_urdf/meshes/link 1.STL" />
      </geometry>
    </collision>
  </link>
  <joint
    name="left joint"
    type="continuous">
    <origin
      xyz="0.1275 0.0565 -0.1625"
      rpy="0 0 -0.078495" />
    <parent
      link="base_link" />
    <child
      link="link 1" />
    <axis
      xyz="0 0 1" />
  </joint>
  <link
    name="link 2">
    <inertial>
      <origin
        xyz="-0.0527917190555129 -0.0394192572917403 0.0315006005679314"
        rpy="0 0 0" />
      <mass
        value="1.17798128734237" />
      <inertia
        ixx="0.00191194326113892"
        ixy="-1.33720688600319E-05"
        ixz="-2.07208909764318E-05"
        iyy="0.00223697342533874"
        iyz="-1.31435323920929E-06"
        izz="0.00376548150056506" />
    </inertial>
    <visual>
      <origin
        xyz="0 0 0"
        rpy="0 0 0" />
      <geometry>
        <mesh
          filename="package://amr_urdf/meshes/link 2.STL" />
      </geometry>
      <material
        name="">
        <color
          rgba="0.752941176470588 0.752941176470588 0.752941176470588 1" />
      </material>
    </visual>
    <collision>
      <origin
        xyz="0 0 0"
        rpy="0 0 0" />
      <geometry>
        <mesh
          filename="package://amr_urdf/meshes/link 2.STL" />
      </geometry>
    </collision>
  </link>
  <joint
    name="right joint"
    type="continuous">
    <origin
      xyz="0.1275 0.0565 0.1625"
      rpy="0 0 -0.015069" />
    <parent
      link="base_link" />
    <child
      link="link 2" />
    <axis
      xyz="0 0 1" />
  </joint>
  <link
    name="link3">
    <inertial>
      <origin
        xyz="0.0210809377858027 -0.0285954874229622 0.000903723675605095"
        rpy="0 0 0" />
      <mass
        value="0.766136855481335" />
      <inertia
        ixx="0.00146321975194456"
        ixy="2.06729659866252E-05"
        ixz="3.65268488338246E-06"
        iyy="0.00155039079723664"
        iyz="-5.12964016248902E-06"
        izz="0.00105695352107657" />
    </inertial>
    <visual>
      <origin
        xyz="0 0 0"
        rpy="0 0 0" />
      <geometry>
        <mesh
          filename="package://amr_urdf/meshes/link3.STL" />
      </geometry>
      <material
        name="">
        <color
          rgba="0.752941176470588 0.752941176470588 0.752941176470588 1" />
      </material>
    </visual>
    <collision>
      <origin
        xyz="0 0 0"
        rpy="0 0 0" />
      <geometry>
        <mesh
          filename="package://amr_urdf/meshes/link3.STL" />
      </geometry>
    </collision>
  </link>
  <joint
    name="back joint"
    type="continuous">
    <origin
      xyz="-0.25 0.0565 0"
      rpy="0 0 0" />
    <parent
      link="base_link" />
    <child
      link="link3" />
    <axis
      xyz="1 0 0" />
  </joint>
</robot>