<?xml version="1.0" encoding="utf-8"?>
<!-- This URDF was automatically created by SolidWorks to URDF Exporter! Originally created by Stephen Brawner (brawner@gmail.com) 
     Commit Version: 1.6.0-4-g7f85cfe  Build Version: 1.6.7995.38578
     For more information, please see http://wiki.ros.org/sw_urdf_exporter -->
<robot
  name="amr_model_2">
  <link
    name="base_link">
    <inertial>
      <origin
        xyz="0.0694808032720803 -4.50796504569695E-07 0.0733703353644319"
        rpy="0 0 0" />
      <mass
        value="3.76763445588817" />
      <inertia
        ixx="0.0766714321789767"
        ixy="-2.41600659565851E-08"
        ixz="1.25967847791078E-07"
        iyy="0.0659904252719117"
        iyz="3.29972382668585E-08"
        izz="0.142086055251958" />
    </inertial>
    <visual>
      <origin
        xyz="0 0 0"
        rpy="0 0 0" />
      <geometry>
        <mesh
          filename="package://amr_model_2/meshes/base_link.STL" />
      </geometry>
      <material
        name="">
        <color
          rgba="0.792156862745098 0.819607843137255 0.933333333333333 1" />
      </material>
    </visual>
    <collision>
      <origin
        xyz="0 0 0"
        rpy="0 0 0" />
      <geometry>
        <mesh
          filename="package://amr_model_2/meshes/base_link.STL" />
      </geometry>
    </collision>
  </link>
  <link
    name="Left_Link">
    <inertial>
      <origin
        xyz="0.0424175601198812 -0.0146631732128588 -8.08649341392242E-05"
        rpy="0 0 0" />
      <mass
        value="0.173725014087237" />
      <inertia
        ixx="6.83670000756998E-05"
        ixy="-1.36459818436927E-06"
        ixz="3.09436550712331E-12"
        iyy="0.000387119697750092"
        iyz="1.6607523648289E-11"
        izz="0.00035643030289182" />
    </inertial>
    <visual>
      <origin
        xyz="0 0 0"
        rpy="0 0 0" />
      <geometry>
        <mesh
          filename="package://amr_model_2/meshes/Left_Link.STL" />
      </geometry>
      <material
        name="">
        <color
          rgba="0.792156862745098 0.819607843137255 0.933333333333333 1" />
      </material>
    </visual>
    <collision>
      <origin
        xyz="0 0 0"
        rpy="0 0 0" />
      <geometry>
        <mesh
          filename="package://amr_model_2/meshes/Left_Link.STL" />
      </geometry>
    </collision>
  </link>
  <joint
    name="Left_Joint"
    type="continuous">
    <origin
      xyz="0.12751 0.1625 0.052812"
      rpy="0 0 0" />
    <parent
      link="base_link" />
    <child
      link="Left_Link" />
    <axis
      xyz="0 0 1" />
  </joint>
  <link
    name="Left_Drive_Link">
    <inertial>
      <origin
        xyz="8.8596630226645E-07 -2.32680975753574E-06 0.000143413644960233"
        rpy="0 0 0" />
      <mass
        value="0.697781408700204" />
      <inertia
        ixx="0.00153904430871612"
        ixy="9.85923455302617E-09"
        ixz="3.83699405213039E-08"
        iyy="0.00153902824005279"
        iyz="-9.12924693848684E-08"
        izz="0.00291644521274641" />
    </inertial>
    <visual>
      <origin
        xyz="0 0 0"
        rpy="0 0 0" />
      <geometry>
        <mesh
          filename="package://amr_model_2/meshes/Left_Drive_Link.STL" />
      </geometry>
      <material
        name="">
        <color
          rgba="0.792156862745098 0.819607843137255 0.933333333333333 1" />
      </material>
    </visual>
    <collision>
      <origin
        xyz="0 0 0"
        rpy="0 0 0" />
      <geometry>
        <mesh
          filename="package://amr_model_2/meshes/Left_Drive_Link.STL" />
      </geometry>
    </collision>
  </link>
  <joint
    name="Left_Drive_Joint"
    type="continuous">
    <origin
      xyz="-0.12751 0.050237 0.0546"
      rpy="0 0 0" />
    <parent
      link="Left_Link" />
    <child
      link="Left_Drive_Link" />
    <axis
      xyz="0 0 -1" />
  </joint>
  <link
    name="Left_Swivel_Link">
    <inertial>
      <origin
        xyz="-0.0156743661652612 4.89580691320768E-07 0.0174191529510675"
        rpy="0 0 0" />
      <mass
        value="0.040333223205091" />
      <inertia
        ixx="5.12022824287161E-05"
        ixy="-3.43232937174314E-10"
        ixz="1.08744968478184E-05"
        iyy="4.78544041648648E-05"
        iyz="1.55991931416432E-09"
        izz="4.83918318766484E-05" />
    </inertial>
    <visual>
      <origin
        xyz="0 0 0"
        rpy="0 0 0" />
      <geometry>
        <mesh
          filename="package://amr_model_2/meshes/Left_Swivel_Link.STL" />
      </geometry>
      <material
        name="">
        <color
          rgba="0.792156862745098 0.819607843137255 0.933333333333333 1" />
      </material>
    </visual>
    <collision>
      <origin
        xyz="0 0 0"
        rpy="0 0 0" />
      <geometry>
        <mesh
          filename="package://amr_model_2/meshes/Left_Swivel_Link.STL" />
      </geometry>
    </collision>
  </link>
  <joint
    name="Left_Swivel_Joint"
    type="continuous">
    <origin
      xyz="0.123 1.2647E-05 -0.0005"
      rpy="0 0 0" />
    <parent
      link="Left_Link" />
    <child
      link="Left_Swivel_Link" />
    <axis
      xyz="0.00010282 0 -1" />
  </joint>
  <link
    name="Left_Castor_Link">
    <inertial>
      <origin
        xyz="2.77555756156289E-15 9.99200722162641E-16 5.55111512312578E-17"
        rpy="0 0 0" />
      <mass
        value="0.16139609361482" />
      <inertia
        ixx="0.00022051365922702"
        ixy="-3.00233475132247E-20"
        ixz="5.11480340615384E-19"
        iyy="0.000220513659227019"
        iyz="-2.57505836012881E-19"
        izz="0.000416796707486866" />
    </inertial>
    <visual>
      <origin
        xyz="0 0 0"
        rpy="0 0 0" />
      <geometry>
        <mesh
          filename="package://amr_model_2/meshes/Left_Castor_Link.STL" />
      </geometry>
      <material
        name="">
        <color
          rgba="0.792156862745098 0.819607843137255 0.933333333333333 1" />
      </material>
    </visual>
    <collision>
      <origin
        xyz="0 0 0"
        rpy="0 0 0" />
      <geometry>
        <mesh
          filename="package://amr_model_2/meshes/Left_Castor_Link.STL" />
      </geometry>
    </collision>
  </link>
  <joint
    name="Left_Castor_Joint"
    type="continuous">
    <origin
      xyz="-0.042008 0 0.075496"
      rpy="0 0 0" />
    <parent
      link="Left_Swivel_Link" />
    <child
      link="Left_Castor_Link" />
    <axis
      xyz="0 0 1" />
  </joint>
  <link
    name="Right_Link">
    <inertial>
      <origin
        xyz="-0.0424147240243436 -0.0146713748826112 8.08649356075497E-05"
        rpy="0 0 0" />
      <mass
        value="0.173725014087434" />
      <inertia
        ixx="6.83664842732682E-05"
        ixy="1.30296341288277E-06"
        ixz="3.09735740186209E-12"
        iyy="0.000387120213534152"
        iyz="-1.66069196324567E-11"
        izz="0.000356430302873432" />
    </inertial>
    <visual>
      <origin
        xyz="0 0 0"
        rpy="0 0 0" />
      <geometry>
        <mesh
          filename="package://amr_model_2/meshes/Right_Link.STL" />
      </geometry>
      <material
        name="">
        <color
          rgba="0.792156862745098 0.819607843137255 0.933333333333333 1" />
      </material>
    </visual>
    <collision>
      <origin
        xyz="0 0 0"
        rpy="0 0 0" />
      <geometry>
        <mesh
          filename="package://amr_model_2/meshes/Right_Link.STL" />
      </geometry>
    </collision>
  </link>
  <joint
    name="Right_Joint"
    type="continuous">
    <origin
      xyz="0.127506259223797 -0.162500000000007 0.0528119631753412"
      rpy="-1.5707963267949 0 3.14159265358979" />
    <parent
      link="base_link" />
    <child
      link="Right_Link" />
    <axis
      xyz="0 0 -1" />
  </joint>
  <link
    name="Right_Drive_Link">
    <inertial>
      <origin
        xyz="-2.1239021292252E-06 -1.29923811575949E-06 -0.0009054152012542"
        rpy="0 0 0" />
      <mass
        value="0.697781408700203" />
      <inertia
        ixx="0.00153903235335043"
        ixy="-1.2098780247133E-08"
        ixz="-8.26668778021354E-08"
        iyy="0.00153904019541848"
        iyz="-5.45229732749373E-08"
        izz="0.00291644521274641" />
    </inertial>
    <visual>
      <origin
        xyz="0 0 0"
        rpy="0 0 0" />
      <geometry>
        <mesh
          filename="package://amr_model_2/meshes/Right_Drive_Link.STL" />
      </geometry>
      <material
        name="">
        <color
          rgba="0.792156862745098 0.819607843137255 0.933333333333333 1" />
      </material>
    </visual>
    <collision>
      <origin
        xyz="0 0 0"
        rpy="0 0 0" />
      <geometry>
        <mesh
          filename="package://amr_model_2/meshes/Right_Drive_Link.STL" />
      </geometry>
    </collision>
  </link>
  <joint
    name="Right_Drive_Joint"
    type="continuous">
    <origin
      xyz="0.1275 0.050262 0.055649"
      rpy="0 0 0" />
    <parent
      link="Right_Link" />
    <child
      link="Right_Drive_Link" />
    <axis
      xyz="0 0 -1" />
  </joint>
  <link
    name="Right_Swivel_Link">
    <inertial>
      <origin
        xyz="0.000413779301244421 0.0156685882902514 0.0174193359997007"
        rpy="0 0 0" />
      <mass
        value="0.0403332724407856" />
      <inertia
        ixx="4.78565029791964E-05"
        ixy="8.8624659607972E-08"
        ixz="-2.85213998640707E-07"
        iyy="5.12000712496557E-05"
        iyz="-1.08706206871853E-05"
        izz="4.83914901628397E-05" />
    </inertial>
    <visual>
      <origin
        xyz="0 0 0"
        rpy="0 0 0" />
      <geometry>
        <mesh
          filename="package://amr_model_2/meshes/Right_Swivel_Link.STL" />
      </geometry>
      <material
        name="">
        <color
          rgba="0.792156862745098 0.819607843137255 0.933333333333333 1" />
      </material>
    </visual>
    <collision>
      <origin
        xyz="0 0 0"
        rpy="0 0 0" />
      <geometry>
        <mesh
          filename="package://amr_model_2/meshes/Right_Swivel_Link.STL" />
      </geometry>
    </collision>
  </link>
  <joint
    name="Right_Swivel_Joint"
    type="continuous">
    <origin
      xyz="-0.122999999495851 -1.11364478370679E-05 0.000500000000000833"
      rpy="1.5707963267949 1.5707963267949 0" />
    <parent
      link="Right_Link" />
    <child
      link="Right_Swivel_Link" />
    <axis
      xyz="0 -9.05402263184918E-05 -0.999999995901234" />
  </joint>
  <link
    name="Right_Castor_Link">
    <inertial>
      <origin
        xyz="7.60406684230386E-06 0.0839855070156855 0.00110705119946175"
        rpy="0 0 0" />
      <mass
        value="0.161396093614818" />
      <inertia
        ixx="0.000220513659228128"
        ixy="1.22623154919319E-11"
        ixz="-4.66657817760277E-10"
        iyy="0.000220649094225962"
        iyz="-5.15414898840514E-06"
        izz="0.000416661272486809" />
    </inertial>
    <visual>
      <origin
        xyz="0 0 0"
        rpy="0 0 0" />
      <geometry>
        <mesh
          filename="package://amr_model_2/meshes/Right_Castor_Link.STL" />
      </geometry>
      <material
        name="">
        <color
          rgba="0.792156862745098 0.819607843137255 0.933333333333333 1" />
      </material>
    </visual>
    <collision>
      <origin
        xyz="0 0 0"
        rpy="0 0 0" />
      <geometry>
        <mesh
          filename="package://amr_model_2/meshes/Right_Castor_Link.STL" />
      </geometry>
    </collision>
  </link>
  <joint
    name="Right_Castor_Joint"
    type="continuous">
    <origin
      xyz="0 -0.041993 0.075504"
      rpy="0 0 0" />
    <parent
      link="Right_Swivel_Link" />
    <child
      link="Right_Castor_Link" />
    <axis
      xyz="0 9.054E-05 -1" />
  </joint>
  <link
    name="Back_Link">
    <inertial>
      <origin
        xyz="-0.0183318680811729 -1.75000319790897E-07 0.000116576900137094"
        rpy="0 0 0" />
      <mass
        value="0.241012788592428" />
      <inertia
        ixx="0.000957865697392896"
        ixy="8.2294642416638E-09"
        ixz="2.93429259516477E-20"
        iyy="9.58018269160901E-05"
        iyz="8.33289584662116E-20"
        izz="0.000880790277251438" />
    </inertial>
    <visual>
      <origin
        xyz="0 0 0"
        rpy="0 0 0" />
      <geometry>
        <mesh
          filename="package://amr_model_2/meshes/Back_Link.STL" />
      </geometry>
      <material
        name="">
        <color
          rgba="0.792156862745098 0.819607843137255 0.933333333333333 1" />
      </material>
    </visual>
    <collision>
      <origin
        xyz="0 0 0"
        rpy="0 0 0" />
      <geometry>
        <mesh
          filename="package://amr_model_2/meshes/Back_Link.STL" />
      </geometry>
    </collision>
  </link>
  <joint
    name="Back_Joint"
    type="continuous">
    <origin
      xyz="-0.249993740776166 0 0.0528119631753474"
      rpy="0 1.5707963267949 0" />
    <parent
      link="base_link" />
    <child
      link="Back_Link" />
    <axis
      xyz="0 0 1" />
  </joint>
  <link
    name="Back_Left_Swivel_Link">
    <inertial>
      <origin
        xyz="0.0156725598865823 -2.26780169731988E-06 0.0174207634206767"
        rpy="0 0 0" />
      <mass
        value="0.0403332300930945" />
      <inertia
        ixx="5.12045014882558E-05"
        ixy="-5.82561977433272E-10"
        ixz="-1.08741942222742E-05"
        iyy="4.78543707256812E-05"
        iyz="-4.45796429473202E-10"
        izz="4.83895848910092E-05" />
    </inertial>
    <visual>
      <origin
        xyz="0 0 0"
        rpy="0 0 0" />
      <geometry>
        <mesh
          filename="package://amr_model_2/meshes/Back_Left_Swivel_Link.STL" />
      </geometry>
      <material
        name="">
        <color
          rgba="0.792156862745098 0.819607843137255 0.933333333333333 1" />
      </material>
    </visual>
    <collision>
      <origin
        xyz="0 0 0"
        rpy="0 0 0" />
      <geometry>
        <mesh
          filename="package://amr_model_2/meshes/Back_Left_Swivel_Link.STL" />
      </geometry>
    </collision>
  </link>
  <joint
    name="Back_Left_Swivel_Joint"
    type="continuous">
    <origin
      xyz="0 0.1605 0.0005"
      rpy="-1.5708 -1.5673 -1.5708" />
    <parent
      link="Back_Link" />
    <child
      link="Back_Left_Swivel_Link" />
    <axis
      xyz="0 0 -1" />
  </joint>
  <link
    name="Back_Left_Castor_Link">
    <inertial>
      <origin
        xyz="4.16333634234434E-17 1.66533453693773E-16 1.66533453693773E-16"
        rpy="0 0 0" />
      <mass
        value="0.16139609361482" />
      <inertia
        ixx="0.00022051365922702"
        ixy="2.96461531539005E-20"
        ixz="-1.27704175471423E-19"
        iyy="0.00022051365922702"
        iyz="-5.29236359766021E-20"
        izz="0.000416796707486867" />
    </inertial>
    <visual>
      <origin
        xyz="0 0 0"
        rpy="0 0 0" />
      <geometry>
        <mesh
          filename="package://amr_model_2/meshes/Back_Left_Castor_Link.STL" />
      </geometry>
      <material
        name="">
        <color
          rgba="0.792156862745098 0.819607843137255 0.933333333333333 1" />
      </material>
    </visual>
    <collision>
      <origin
        xyz="0 0 0"
        rpy="0 0 0" />
      <geometry>
        <mesh
          filename="package://amr_model_2/meshes/Back_Left_Castor_Link.STL" />
      </geometry>
    </collision>
  </link>
  <joint
    name="Back_Left_Castor_Joint"
    type="continuous">
    <origin
      xyz="0.042 0 0.0755"
      rpy="1.5708 -0.060395 0" />
    <parent
      link="Back_Left_Swivel_Link" />
    <child
      link="Back_Left_Castor_Link" />
    <axis
      xyz="0 0 1" />
  </joint>
  <link
    name="Back_RIght_Swivel_Link">
    <inertial>
      <origin
        xyz="0.00013823316124606 0.0156719328859507 0.0174207598258361"
        rpy="0 0 0" />
      <mass
        value="0.0403332394157405" />
      <inertia
        ixx="4.78545822536645E-05"
        ixy="2.96438047832296E-08"
        ixz="-9.3894180715874E-08"
        iyy="5.12042103043664E-05"
        iyz="-1.08737688270406E-05"
        izz="4.83895716899988E-05" />
    </inertial>
    <visual>
      <origin
        xyz="0 0 0"
        rpy="0 0 0" />
      <geometry>
        <mesh
          filename="package://amr_model_2/meshes/Back_RIght_Swivel_Link.STL" />
      </geometry>
      <material
        name="">
        <color
          rgba="0.792156862745098 0.819607843137255 0.933333333333333 1" />
      </material>
    </visual>
    <collision>
      <origin
        xyz="0 0 0"
        rpy="0 0 0" />
      <geometry>
        <mesh
          filename="package://amr_model_2/meshes/Back_RIght_Swivel_Link.STL" />
      </geometry>
    </collision>
  </link>
  <joint
    name="Back_RIght_Swivel_Joint"
    type="continuous">
    <origin
      xyz="0 -0.1605 0.0005"
      rpy="1.5708 0 1.5708" />
    <parent
      link="Back_Link" />
    <child
      link="Back_RIght_Swivel_Link" />
    <axis
      xyz="0 0 -1" />
  </joint>
  <link
    name="Back_Right_Castor_Link">
    <inertial>
      <origin
        xyz="-1.11022302462516E-16 3.88578058618805E-16 7.7715611723761E-16"
        rpy="0 0 0" />
      <mass
        value="0.161396093614819" />
      <inertia
        ixx="0.000220513659227019"
        ixy="-9.48676900924816E-20"
        ixz="-5.08133948364028E-19"
        iyy="0.000220513659227019"
        iyz="-8.70965350326991E-20"
        izz="0.000416796707486865" />
    </inertial>
    <visual>
      <origin
        xyz="0 0 0"
        rpy="0 0 0" />
      <geometry>
        <mesh
          filename="package://amr_model_2/meshes/Back_Right_Castor_Link.STL" />
      </geometry>
      <material
        name="">
        <color
          rgba="0.792156862745098 0.819607843137255 0.933333333333333 1" />
      </material>
    </visual>
    <collision>
      <origin
        xyz="0 0 0"
        rpy="0 0 0" />
      <geometry>
        <mesh
          filename="package://amr_model_2/meshes/Back_Right_Castor_Link.STL" />
      </geometry>
    </collision>
  </link>
  <joint
    name="Back_Right_Castor_Joint"
    type="continuous">
    <origin
      xyz="0.00036509 0.041998 0.0755"
      rpy="1.5708 0.3931 1.5621" />
    <parent
      link="Back_RIght_Swivel_Link" />
    <child
      link="Back_Right_Castor_Link" />
    <axis
      xyz="0 0 1" />
  </joint>
</robot>