<?xml version="1.0" encoding="utf-8"?>
<!-- This URDF was automatically created by SolidWorks to URDF Exporter! Originally created by Stephen Brawner (brawner@gmail.com) 
     Commit Version: 1.6.0-4-g7f85cfe  Build Version: 1.6.7995.38578
     For more information, please see http://wiki.ros.org/sw_urdf_exporter -->
<robot
  name="full_amr">
  <link
    name="base_link">
    <inertial>
      <origin
        xyz="4.39643166745829E-07 0.0677968819277461 -0.0609502708124765"
        rpy="0 0 0" />
      <mass
        value="3.86321584157732" />
      <inertia
        ixx="0.066007396363459"
        ixy="2.41600659458609E-08"
        ixz="-3.2997238541756E-08"
        iyy="0.0766853600125674"
        iyz="1.25967847791028E-07"
        izz="0.142096939827593" />
    </inertial>
    <visual>
      <origin
        xyz="0 0 0"
        rpy="0 0 0" />
      <geometry>
        <mesh
          filename="package://full_amr/meshes/base_link.STL" />
      </geometry>
      <material
        name="">
        <color
          rgba="0.792156862745098 0.819607843137255 0.933333333333333 1" />
      </material>
    </visual>
    <collision>
      <origin
        xyz="0 0 0"
        rpy="0 0 0" />
      <geometry>
        <mesh
          filename="package://full_amr/meshes/base_link.STL" />
      </geometry>
    </collision>
  </link>
  <link
    name="right_pivot">
    <inertial>
      <origin
        xyz="6.72247869802078E-05 0.0421664270030071 0.0145721439576452"
        rpy="0 0 0" />
      <mass
        value="0.173980611077858" />
      <inertia
        ixx="0.000356722830721263"
        ixy="1.30770286233331E-09"
        ixz="-7.76891728080055E-08"
        iyy="6.86775402465423E-05"
        iyz="1.33664947005398E-06"
        izz="0.000387144140256692" />
    </inertial>
    <visual>
      <origin
        xyz="0 0 0"
        rpy="0 0 0" />
      <geometry>
        <mesh
          filename="package://full_amr/meshes/right_pivot.STL" />
      </geometry>
      <material
        name="">
        <color
          rgba="0.792156862745098 0.819607843137255 0.933333333333333 1" />
      </material>
    </visual>
    <collision>
      <origin
        xyz="0 0 0"
        rpy="0 0 0" />
      <geometry>
        <mesh
          filename="package://full_amr/meshes/right_pivot.STL" />
      </geometry>
    </collision>
  </link>
  <joint
    name="right_pivot_hinge"
    type="continuous">
    <origin
      xyz="0.1625 0.1275 -0.081"
      rpy="0 0 0" />
    <parent
      link="base_link" />
    <child
      link="right_pivot" />
    <axis
      xyz="1 0 0" />
  </joint>
  <link
    name="right_wheel">
    <inertial>
      <origin
        xyz="8.82920752710899E-08 -1.86536986968022E-08 -1.07619964537231E-05"
        rpy="0 0 0" />
      <mass
        value="0.671865219229547" />
      <inertia
        ixx="0.00152382831042098"
        ixy="-2.99658197533872E-09"
        ixz="-7.08391619183914E-10"
        iyy="0.00152383788550933"
        iyz="3.46009207166289E-10"
        izz="0.00291423163667508" />
    </inertial>
    <visual>
      <origin
        xyz="0 0 0"
        rpy="0 0 0" />
      <geometry>
        <mesh
          filename="package://full_amr/meshes/right_wheel.STL" />
      </geometry>
      <material
        name="">
        <color
          rgba="0.792156862745098 0.819607843137255 0.933333333333333 1" />
      </material>
    </visual>
    <collision>
      <origin
        xyz="0 0 0"
        rpy="0 0 0" />
      <geometry>
        <mesh
          filename="package://full_amr/meshes/right_wheel.STL" />
      </geometry>
    </collision>
  </link>
  <joint
    name="right_wheel_hinge"
    type="continuous">
    <origin
      xyz="0.0606000000000009 -0.127499999999999 -0.0502500000000001"
      rpy="1.5707963267949 0 1.5707963267949" />
    <parent
      link="right_pivot" />
    <child
      link="right_wheel" />
    <axis
      xyz="0 0 -1" />
  </joint>
  <link
    name="FR_swivel">
    <inertial>
      <origin
        xyz="2.10104722961346E-06 -0.0156725739371232 -0.0264207645470237"
        rpy="0 0 0" />
      <mass
        value="0.0403332237188925" />
      <inertia
        ixx="4.78544037601178E-05"
        ixy="-6.87574813164264E-10"
        ixz="-4.41750017652362E-10"
        iyy="5.12045181984068E-05"
        iyz="-1.08742076360189E-05"
        izz="4.83895954535559E-05" />
    </inertial>
    <visual>
      <origin
        xyz="0 0 0"
        rpy="0 0 0" />
      <geometry>
        <mesh
          filename="package://full_amr/meshes/FR_swivel.STL" />
      </geometry>
      <material
        name="">
        <color
          rgba="0.792156862745098 0.819607843137255 0.933333333333333 1" />
      </material>
    </visual>
    <collision>
      <origin
        xyz="0 0 0"
        rpy="0 0 0" />
      <geometry>
        <mesh
          filename="package://full_amr/meshes/FR_swivel.STL" />
      </geometry>
    </collision>
  </link>
  <joint
    name="FR_swivel_hinge"
    type="continuous">
    <origin
      xyz="0.000499999999998585 0.123000000000001 0.00900000000000202"
      rpy="0 0 0" />
    <parent
      link="right_pivot" />
    <child
      link="FR_swivel" />
    <axis
      xyz="0 0 1" />
  </joint>
  <link
    name="FR_castor">
    <inertial>
      <origin
        xyz="-5.55111512312578E-17 0 -2.77555756156289E-17"
        rpy="0 0 0" />
      <mass
        value="0.161396093614819" />
      <inertia
        ixx="0.000416796707486866"
        ixy="2.73011852206279E-18"
        ixz="-6.94855921025798E-19"
        iyy="0.000220513659227019"
        iyz="2.83696566838897E-20"
        izz="0.000220513659227019" />
    </inertial>
    <visual>
      <origin
        xyz="0 0 0"
        rpy="0 0 0" />
      <geometry>
        <mesh
          filename="package://full_amr/meshes/FR_castor.STL" />
      </geometry>
      <material
        name="">
        <color
          rgba="0.792156862745098 0.819607843137255 0.933333333333333 1" />
      </material>
    </visual>
    <collision>
      <origin
        xyz="0 0 0"
        rpy="0 0 0" />
      <geometry>
        <mesh
          filename="package://full_amr/meshes/FR_castor.STL" />
      </geometry>
    </collision>
  </link>
  <joint
    name="FR_castor_hinge"
    type="continuous">
    <origin
      xyz="0.00100000000000031 -0.0420000000000006 -0.0845000000000024"
      rpy="0 0 0" />
    <parent
      link="FR_swivel" />
    <child
      link="FR_castor" />
    <axis
      xyz="1 0 0" />
  </joint>
  <link
    name="left_pivot">
    <inertial>
      <origin
        xyz="6.72247985100405E-05 0.0421520181325834 0.0146137713653624"
        rpy="0 0 0" />
      <mass
        value="0.173980611061865" />
      <inertia
        ixx="0.000356722830492717"
        ixy="1.38441365793848E-09"
        ixz="-7.76878439844708E-08"
        iyy="6.86752111533773E-05"
        iyz="1.0221976196466E-06"
        izz="0.000387146469119925" />
    </inertial>
    <visual>
      <origin
        xyz="0 0 0"
        rpy="0 0 0" />
      <geometry>
        <mesh
          filename="package://full_amr/meshes/left_pivot.STL" />
      </geometry>
      <material
        name="">
        <color
          rgba="0.792156862745098 0.819607843137255 0.933333333333333 1" />
      </material>
    </visual>
    <collision>
      <origin
        xyz="0 0 0"
        rpy="0 0 0" />
      <geometry>
        <mesh
          filename="package://full_amr/meshes/left_pivot.STL" />
      </geometry>
    </collision>
  </link>
  <joint
    name="left_pivot_hinge"
    type="continuous">
    <origin
      xyz="-0.1625 0.1275 -0.081"
      rpy="0 0 0" />
    <parent
      link="base_link" />
    <child
      link="left_pivot" />
    <axis
      xyz="1 0 0" />
  </joint>
  <link
    name="left_wheel">
    <inertial>
      <origin
        xyz="5.10511360130028E-08 7.44125832297739E-08 -1.07619964536676E-05"
        rpy="0 0 0" />
      <mass
        value="0.671865219229547" />
      <inertia
        ixx="0.00152383860116951"
        ixy="-1.27075746565581E-09"
        ixz="-5.90967111167512E-10"
        iyy="0.00152382759476079"
        iyz="-5.21822709906712E-10"
        izz="0.00291423163667508" />
    </inertial>
    <visual>
      <origin
        xyz="0 0 0"
        rpy="0 0 0" />
      <geometry>
        <mesh
          filename="package://full_amr/meshes/left_wheel.STL" />
      </geometry>
      <material
        name="">
        <color
          rgba="0.792156862745098 0.819607843137255 0.933333333333333 1" />
      </material>
    </visual>
    <collision>
      <origin
        xyz="0 0 0"
        rpy="0 0 0" />
      <geometry>
        <mesh
          filename="package://full_amr/meshes/left_wheel.STL" />
      </geometry>
    </collision>
  </link>
  <joint
    name="left_wheel_hinge"
    type="continuous">
    <origin
      xyz="-0.0606000000000003 -0.127450321712043 -0.050375867193494"
      rpy="3.14159265358979 -1.5707963267949 0" />
    <parent
      link="left_pivot" />
    <child
      link="left_wheel" />
    <axis
      xyz="0 0 -1" />
  </joint>
  <link
    name="FL_swivel">
    <inertial>
      <origin
        xyz="6.5511778461258E-05 -0.0156463149501383 -0.0264362233956825"
        rpy="0 0 0" />
      <mass
        value="0.0403332363730702" />
      <inertia
        ixx="4.78543933221479E-05"
        ixy="-1.42826551762756E-08"
        ixz="4.35430090190855E-08"
        iyy="5.12258920158362E-05"
        iyz="-1.08712913722346E-05"
        izz="4.83681025928456E-05" />
    </inertial>
    <visual>
      <origin
        xyz="0 0 0"
        rpy="0 0 0" />
      <geometry>
        <mesh
          filename="package://full_amr/meshes/FL_swivel.STL" />
      </geometry>
      <material
        name="">
        <color
          rgba="0.792156862745098 0.819607843137255 0.933333333333333 1" />
      </material>
    </visual>
    <collision>
      <origin
        xyz="0 0 0"
        rpy="0 0 0" />
      <geometry>
        <mesh
          filename="package://full_amr/meshes/FL_swivel.STL" />
      </geometry>
    </collision>
  </link>
  <joint
    name="FL_swivel_hinge"
    type="continuous">
    <origin
      xyz="0.000499999999999945 0.122991053569608 0.00912144406537516"
      rpy="0 0 0" />
    <parent
      link="left_pivot" />
    <child
      link="FL_swivel" />
    <axis
      xyz="0 -0.000987385793199488 0.999999512534529" />
  </joint>
  <link
    name="FL_castor">
    <inertial>
      <origin
        xyz="-2.77555756156289E-17 0 -2.77555756156289E-17"
        rpy="0 0 0" />
      <mass
        value="0.161396093614819" />
      <inertia
        ixx="0.000416793494356327"
        ixy="7.94148674684207E-07"
        ixz="7.84131501411023E-10"
        iyy="0.000220516872354425"
        iyz="3.17259789254566E-12"
        izz="0.000220513659230152" />
    </inertial>
    <visual>
      <origin
        xyz="0 0 0"
        rpy="0 0 0" />
      <geometry>
        <mesh
          filename="package://full_amr/meshes/FL_castor.STL" />
      </geometry>
      <material
        name="">
        <color
          rgba="0.792156862745098 0.819607843137255 0.933333333333333 1" />
      </material>
    </visual>
    <collision>
      <origin
        xyz="0 0 0"
        rpy="0 0 0" />
      <geometry>
        <mesh
          filename="package://full_amr/meshes/FL_castor.STL" />
      </geometry>
    </collision>
  </link>
  <joint
    name="FL_castor_hinge"
    type="continuous">
    <origin
      xyz="-0.000830061024273993 -0.0419202476273774 -0.0845414326679843"
      rpy="0 0 0" />
    <parent
      link="FL_swivel" />
    <child
      link="FL_castor" />
    <axis
      xyz="0.999991815024994 0.00404596923608611 0" />
  </joint>
  <link
    name="back_pivot">
    <inertial>
      <origin
        xyz="1.44973360508818E-16 0.000116576900137194 0.0183318680820081"
        rpy="0 0 0" />
      <mass
        value="0.241012788592428" />
      <inertia
        ixx="9.58018268375299E-05"
        ixy="-3.72699795917691E-20"
        ixz="-1.36527641082292E-20"
        iyy="0.000880790277251433"
        iyz="4.53865844064651E-21"
        izz="0.000957865697471451" />
    </inertial>
    <visual>
      <origin
        xyz="0 0 0"
        rpy="0 0 0" />
      <geometry>
        <mesh
          filename="package://full_amr/meshes/back_pivot.STL" />
      </geometry>
      <material
        name="">
        <color
          rgba="0.792156862745098 0.819607843137255 0.933333333333333 1" />
      </material>
    </visual>
    <collision>
      <origin
        xyz="0 0 0"
        rpy="0 0 0" />
      <geometry>
        <mesh
          filename="package://full_amr/meshes/back_pivot.STL" />
      </geometry>
    </collision>
  </link>
  <joint
    name="back_pivot_hinge"
    type="continuous">
    <origin
      xyz="0 -0.25 -0.081"
      rpy="0 0 0" />
    <parent
      link="base_link" />
    <child
      link="back_pivot" />
    <axis
      xyz="0 -1 0" />
  </joint>
  <link
    name="BR_swivel">
    <inertial>
      <origin
        xyz="-2.86806979956089E-05 -0.0156725402272886 -0.0264207636386582"
        rpy="0 0 0" />
      <mass
        value="0.0403332273268806" />
      <inertia
        ixx="4.78543953407379E-05"
        ixy="5.89296547462546E-09"
        ixz="-2.1798803371086E-08"
        iyy="5.12044981326952E-05"
        iyz="-1.08741782741284E-05"
        izz="4.838958990946E-05" />
    </inertial>
    <visual>
      <origin
        xyz="0 0 0"
        rpy="0 0 0" />
      <geometry>
        <mesh
          filename="package://full_amr/meshes/BR_swivel.STL" />
      </geometry>
      <material
        name="">
        <color
          rgba="0.792156862745098 0.819607843137255 0.933333333333333 1" />
      </material>
    </visual>
    <collision>
      <origin
        xyz="0 0 0"
        rpy="0 0 0" />
      <geometry>
        <mesh
          filename="package://full_amr/meshes/BR_swivel.STL" />
      </geometry>
    </collision>
  </link>
  <joint
    name="BR_swivel_hinge"
    type="continuous">
    <origin
      xyz="0.160500000000001 0.000500000000000667 0.00899999999999893"
      rpy="0 0 0" />
    <parent
      link="back_pivot" />
    <child
      link="BR_swivel" />
    <axis
      xyz="0 0 1" />
  </joint>
  <link
    name="BR_castor">
    <inertial>
      <origin
        xyz="7.49400541621981E-16 3.33066907387547E-16 -3.05311331771918E-16"
        rpy="0 0 0" />
      <mass
        value="0.16139609361482" />
      <inertia
        ixx="0.000416795950313433"
        ixy="-3.8551230350754E-07"
        ixz="-1.31224261119139E-18"
        iyy="0.000220514416400452"
        iyz="-1.72229331427263E-20"
        izz="0.000220513659227019" />
    </inertial>
    <visual>
      <origin
        xyz="0 0 0"
        rpy="0 0 0" />
      <geometry>
        <mesh
          filename="package://full_amr/meshes/BR_castor.STL" />
      </geometry>
      <material
        name="">
        <color
          rgba="0.792156862745098 0.819607843137255 0.933333333333333 1" />
      </material>
    </visual>
    <collision>
      <origin
        xyz="0 0 0"
        rpy="0 0 0" />
      <geometry>
        <mesh
          filename="package://full_amr/meshes/BR_castor.STL" />
      </geometry>
    </collision>
  </link>
  <joint
    name="BR_castor_hinge"
    type="continuous">
    <origin
      xyz="0.000917507259500183 -0.0420018830581295 -0.0844999999999997"
      rpy="0 0 0" />
    <parent
      link="BR_swivel" />
    <child
      link="BR_castor" />
    <axis
      xyz="-0.999998071218656 0.00196406694564723 0" />
  </joint>
  <link
    name="BL_swivel">
    <inertial>
      <origin
        xyz="-8.23621583788681E-05 -0.0156723375221494 -0.0264207621674671"
        rpy="0 0 0" />
      <mass
        value="0.040333232832404" />
      <inertia
        ixx="4.7854441195365E-05"
        ixy="1.73687216368048E-08"
        ixz="-5.90443392248631E-08"
        iyy="5.12044011536028E-05"
        iyz="-1.08740264445735E-05"
        izz="4.83895789718872E-05" />
    </inertial>
    <visual>
      <origin
        xyz="0 0 0"
        rpy="0 0 0" />
      <geometry>
        <mesh
          filename="package://full_amr/meshes/BL_swivel.STL" />
      </geometry>
      <material
        name="">
        <color
          rgba="0.792156862745098 0.819607843137255 0.933333333333333 1" />
      </material>
    </visual>
    <collision>
      <origin
        xyz="0 0 0"
        rpy="0 0 0" />
      <geometry>
        <mesh
          filename="package://full_amr/meshes/BL_swivel.STL" />
      </geometry>
    </collision>
  </link>
  <joint
    name="BL_swivel_hinge"
    type="continuous">
    <origin
      xyz="-0.160499999999999 0.000499999999999445 0.00900000000000113"
      rpy="0 0 0" />
    <parent
      link="back_pivot" />
    <child
      link="BL_swivel" />
    <axis
      xyz="0 0 1" />
  </joint>
  <link
    name="BL_castor">
    <inertial>
      <origin
        xyz="2.77555756156289E-17 0 -2.77555756156289E-17"
        rpy="0 0 0" />
      <mass
        value="0.16139609361482" />
      <inertia
        ixx="0.000416791006545238"
        ixy="-1.05781175070598E-06"
        ixz="-1.31515100667501E-18"
        iyy="0.000220519360168647"
        iyz="-2.7890663951698E-20"
        izz="0.000220513659227019" />
    </inertial>
    <visual>
      <origin
        xyz="0 0 0"
        rpy="0 0 0" />
      <geometry>
        <mesh
          filename="package://full_amr/meshes/BL_castor.STL" />
      </geometry>
      <material
        name="">
        <color
          rgba="0.792156862745098 0.819607843137255 0.933333333333333 1" />
      </material>
    </visual>
    <collision>
      <origin
        xyz="0 0 0"
        rpy="0 0 0" />
      <geometry>
        <mesh
          filename="package://full_amr/meshes/BL_castor.STL" />
      </geometry>
    </collision>
  </link>
  <joint
    name="BL_castor_hinge"
    type="continuous">
    <origin
      xyz="-0.00122633583817874 -0.0419940007669185 -0.0845"
      rpy="0 0 0" />
    <parent
      link="BL_swivel" />
    <child
      link="BL_castor" />
    <axis
      xyz="-0.999985477648034 0.00538929429831941 0" />
  </joint>
</robot>