<?xml version="1.0" encoding="utf-8"?>
<!-- This URDF was automatically created by SolidWorks to URDF Exporter! Originally created by Stephen Brawner (brawner@gmail.com) 
     Commit Version: 1.6.0-4-g7f85cfe  Build Version: 1.6.7995.38578
     For more information, please see http://wiki.ros.org/sw_urdf_exporter -->
<robot
  name="basic_amr">
  <link
    name="base_link">
    <inertial>
      <origin
        xyz="5.63544150455062E-06 0.0585613447753292 -0.0614713657844919"
        rpy="0 0 0" />
      <mass
        value="4.45218985232546" />
      <inertia
        ixx="0.066816643851739"
        ixy="2.67754716420424E-08"
        ixz="-1.8837558389635E-07"
        iyy="0.0777035053703119"
        iyz="2.79926678789631E-06"
        izz="0.143829093805577" />
    </inertial>
    <visual>
      <origin
        xyz="0 0 0"
        rpy="0 0 0" />
      <geometry>
        <mesh
          filename="package://basic_amr/meshes/base_link.STL" />
      </geometry>
      <material
        name="">
        <color
          rgba="0.792156862745098 0.819607843137255 0.933333333333333 1" />
      </material>
    </visual>
    <collision>
      <origin
        xyz="0 0 0"
        rpy="0 0 0" />
      <geometry>
        <mesh
          filename="package://basic_amr/meshes/base_link.STL" />
      </geometry>
    </collision>
  </link>
  <link
    name="right_wheel">
    <inertial>
      <origin
        xyz="-8.82677809332737E-08 1.8768321230489E-08 -1.07619964537231E-05"
        rpy="0 0 0" />
      <mass
        value="0.671865219229547" />
      <inertia
        ixx="0.00152382830265562"
        ixy="-2.98413960790954E-09"
        ixz="7.07941783230494E-10"
        iyy="0.00152383789327469"
        iyz="-3.46928687264092E-10"
        izz="0.00291423163667509" />
    </inertial>
    <visual>
      <origin
        xyz="0 0 0"
        rpy="0 0 0" />
      <geometry>
        <mesh
          filename="package://basic_amr/meshes/right_wheel.STL" />
      </geometry>
      <material
        name="">
        <color
          rgba="0.792156862745098 0.819607843137255 0.933333333333333 1" />
      </material>
    </visual>
    <collision>
      <origin
        xyz="0 0 0"
        rpy="0 0 0" />
      <geometry>
        <mesh
          filename="package://basic_amr/meshes/right_wheel.STL" />
      </geometry>
    </collision>
  </link>
  <joint
    name="right_wheel_hinge"
    type="continuous">
    <origin
      xyz="0.2231 0 -0.13125"
      rpy="1.5708 0 1.5708" />
    <parent
      link="base_link" />
    <child
      link="right_wheel" />
    <axis
      xyz="0 0 -1" />
  </joint>
  <link
    name="left_wheel">
    <inertial>
      <origin
        xyz="-7.44125831786402E-08 5.10511359796595E-08 -1.07619964536954E-05"
        rpy="0 0 0" />
      <mass
        value="0.671865219229546" />
      <inertia
        ixx="0.00152382759476079"
        ixy="1.27075746572592E-09"
        ixz="5.21822709261331E-10"
        iyy="0.00152383860116951"
        iyz="-5.9096710142078E-10"
        izz="0.00291423163667508" />
    </inertial>
    <visual>
      <origin
        xyz="0 0 0"
        rpy="0 0 0" />
      <geometry>
        <mesh
          filename="package://basic_amr/meshes/left_wheel.STL" />
      </geometry>
      <material
        name="">
        <color
          rgba="0.792156862745098 0.819607843137255 0.933333333333333 1" />
      </material>
    </visual>
    <collision>
      <origin
        xyz="0 0 0"
        rpy="0 0 0" />
      <geometry>
        <mesh
          filename="package://basic_amr/meshes/left_wheel.STL" />
      </geometry>
    </collision>
  </link>
  <joint
    name="left_wheel_hinge"
    type="continuous">
    <origin
      xyz="-0.2231 0 -0.13125"
      rpy="3.1416 -1.5708 0" />
    <parent
      link="base_link" />
    <child
      link="left_wheel" />
    <axis
      xyz="0 0 -1" />
  </joint>
  <link
    name="swivel_FR">
    <inertial>
      <origin
        xyz="2.10863983640674E-06 -0.0155771680202314 -0.0262317388766869"
        rpy="0 0 0" />
      <mass
        value="0.0401879953591251" />
      <inertia
        ixx="4.73544910464119E-05"
        ixy="-6.8851690410037E-10"
        ixz="-4.43617183457905E-10"
        iyy="5.07216320491779E-05"
        iyz="-1.0672961583097E-05"
        izz="4.82016109048881E-05" />
    </inertial>
    <visual>
      <origin
        xyz="0 0 0"
        rpy="0 0 0" />
      <geometry>
        <mesh
          filename="package://basic_amr/meshes/swivel_FR.STL" />
      </geometry>
      <material
        name="">
        <color
          rgba="0.792156862745098 0.819607843137255 0.933333333333333 1" />
      </material>
    </visual>
    <collision>
      <origin
        xyz="0 0 0"
        rpy="0 0 0" />
      <geometry>
        <mesh
          filename="package://basic_amr/meshes/swivel_FR.STL" />
      </geometry>
    </collision>
  </link>
  <joint
    name="swivel_FR_hinge"
    type="continuous">
    <origin
      xyz="0.163 0.2505 -0.072"
      rpy="0 0 0" />
    <parent
      link="base_link" />
    <child
      link="swivel_FR" />
    <axis
      xyz="0 0 1" />
  </joint>
  <link
    name="castor_FR">
    <inertial>
      <origin
        xyz="-2.77555756156289E-17 0 -5.55111512312578E-17"
        rpy="0 0 0" />
      <mass
        value="0.161396093614819" />
      <inertia
        ixx="0.000220513659227019"
        ixy="-8.16892691547843E-20"
        ixz="-6.55966950108417E-19"
        iyy="0.000220513659227019"
        iyz="2.72239433110982E-19"
        izz="0.000416796707486866" />
    </inertial>
    <visual>
      <origin
        xyz="0 0 0"
        rpy="0 0 0" />
      <geometry>
        <mesh
          filename="package://basic_amr/meshes/castor_FR.STL" />
      </geometry>
      <material
        name="">
        <color
          rgba="0.792156862745098 0.819607843137255 0.933333333333333 1" />
      </material>
    </visual>
    <collision>
      <origin
        xyz="0 0 0"
        rpy="0 0 0" />
      <geometry>
        <mesh
          filename="package://basic_amr/meshes/castor_FR.STL" />
      </geometry>
    </collision>
  </link>
  <joint
    name="castor_FR_hinge"
    type="continuous">
    <origin
      xyz="0.00100000000000061 -0.0420375051343131 -0.0815575197240634"
      rpy="1.5707963267949 0 1.5707963267949" />
    <parent
      link="swivel_FR" />
    <child
      link="castor_FR" />
    <axis
      xyz="0 0 1" />
  </joint>
  <link
    name="swivel_FL">
    <inertial>
      <origin
        xyz="2.10863983640674E-06 -0.0155771680202314 -0.0262317388766873"
        rpy="0 0 0" />
      <mass
        value="0.0401879953591256" />
      <inertia
        ixx="4.73544910464128E-05"
        ixy="-6.8851690414419E-10"
        ixz="-4.43617183428621E-10"
        iyy="5.0721632049179E-05"
        iyz="-1.0672961583097E-05"
        izz="4.82016109048895E-05" />
    </inertial>
    <visual>
      <origin
        xyz="0 0 0"
        rpy="0 0 0" />
      <geometry>
        <mesh
          filename="package://basic_amr/meshes/swivel_FL.STL" />
      </geometry>
      <material
        name="">
        <color
          rgba="0.792156862745098 0.819607843137255 0.933333333333333 1" />
      </material>
    </visual>
    <collision>
      <origin
        xyz="0 0 0"
        rpy="0 0 0" />
      <geometry>
        <mesh
          filename="package://basic_amr/meshes/swivel_FL.STL" />
      </geometry>
    </collision>
  </link>
  <joint
    name="swivel_FL_hinge"
    type="continuous">
    <origin
      xyz="-0.162 0.2505 -0.072"
      rpy="0 0 0" />
    <parent
      link="base_link" />
    <child
      link="swivel_FL" />
    <axis
      xyz="0 0 1" />
  </joint>
  <link
    name="castor_FL">
    <inertial>
      <origin
        xyz="-3.02535774210355E-15 -3.88578058618805E-16 -8.60422844084496E-16"
        rpy="0 0 0" />
      <mass
        value="0.16139609361482" />
      <inertia
        ixx="0.00022051365922702"
        ixy="-6.42031398444213E-21"
        ixz="1.98053690680625E-19"
        iyy="0.00022051365922702"
        iyz="-1.29205539932574E-18"
        izz="0.000416796707486866" />
    </inertial>
    <visual>
      <origin
        xyz="0 0 0"
        rpy="0 0 0" />
      <geometry>
        <mesh
          filename="package://basic_amr/meshes/castor_FL.STL" />
      </geometry>
      <material
        name="">
        <color
          rgba="0.792156862745098 0.819607843137255 0.933333333333333 1" />
      </material>
    </visual>
    <collision>
      <origin
        xyz="0 0 0"
        rpy="0 0 0" />
      <geometry>
        <mesh
          filename="package://basic_amr/meshes/castor_FL.STL" />
      </geometry>
    </collision>
  </link>
  <joint
    name="castor_FL_hinge"
    type="continuous">
    <origin
      xyz="0.001 -0.042038 -0.081558"
      rpy="1.5708 0 1.5708" />
    <parent
      link="swivel_FL" />
    <child
      link="castor_FL" />
    <axis
      xyz="0 0 1" />
  </joint>
  <link
    name="swivel_BR">
    <inertial>
      <origin
        xyz="2.10863983626797E-06 -0.0155771680202312 -0.0262317388766873"
        rpy="0 0 0" />
      <mass
        value="0.0401879953591256" />
      <inertia
        ixx="4.73544910464123E-05"
        ixy="-6.88516904357155E-10"
        ixz="-4.43617183373066E-10"
        iyy="5.07216320491788E-05"
        iyz="-1.0672961583097E-05"
        izz="4.8201610904889E-05" />
    </inertial>
    <visual>
      <origin
        xyz="0 0 0"
        rpy="0 0 0" />
      <geometry>
        <mesh
          filename="package://basic_amr/meshes/swivel_BR.STL" />
      </geometry>
      <material
        name="">
        <color
          rgba="0.792156862745098 0.819607843137255 0.933333333333333 1" />
      </material>
    </visual>
    <collision>
      <origin
        xyz="0 0 0"
        rpy="0 0 0" />
      <geometry>
        <mesh
          filename="package://basic_amr/meshes/swivel_BR.STL" />
      </geometry>
    </collision>
  </link>
  <joint
    name="swivel_BR_hinge"
    type="continuous">
    <origin
      xyz="0.1605 -0.2495 -0.072"
      rpy="0 0 0" />
    <parent
      link="base_link" />
    <child
      link="swivel_BR" />
    <axis
      xyz="0 0 1" />
  </joint>
  <link
    name="castor_BR">
    <inertial>
      <origin
        xyz="5.55111512312578E-17 0 -2.77555756156289E-17"
        rpy="0 0 0" />
      <mass
        value="0.161396093614819" />
      <inertia
        ixx="0.000220513659227019"
        ixy="-1.13046961561861E-20"
        ixz="2.21442502435767E-19"
        iyy="0.000220513659227019"
        iyz="-1.38450739983862E-18"
        izz="0.000416796707486866" />
    </inertial>
    <visual>
      <origin
        xyz="0 0 0"
        rpy="0 0 0" />
      <geometry>
        <mesh
          filename="package://basic_amr/meshes/castor_BR.STL" />
      </geometry>
      <material
        name="">
        <color
          rgba="0.792156862745098 0.819607843137255 0.933333333333333 1" />
      </material>
    </visual>
    <collision>
      <origin
        xyz="0 0 0"
        rpy="0 0 0" />
      <geometry>
        <mesh
          filename="package://basic_amr/meshes/castor_BR.STL" />
      </geometry>
    </collision>
  </link>
  <joint
    name="castor_BR_hinge"
    type="continuous">
    <origin
      xyz="0.001 -0.042038 -0.081558"
      rpy="1.5708 0 1.5708" />
    <parent
      link="swivel_BR" />
    <child
      link="castor_BR" />
    <axis
      xyz="0 0 1" />
  </joint>
  <link
    name="swivel_BL">
    <inertial>
      <origin
        xyz="2.10863983632348E-06 -0.0155771680202315 -0.0262317388766868"
        rpy="0 0 0" />
      <mass
        value="0.0401879953591248" />
      <inertia
        ixx="4.73544910464117E-05"
        ixy="-6.88516903827156E-10"
        ixz="-4.43617183562825E-10"
        iyy="5.07216320491788E-05"
        iyz="-1.0672961583097E-05"
        izz="4.82016109048888E-05" />
    </inertial>
    <visual>
      <origin
        xyz="0 0 0"
        rpy="0 0 0" />
      <geometry>
        <mesh
          filename="package://basic_amr/meshes/swivel_BL.STL" />
      </geometry>
      <material
        name="">
        <color
          rgba="0.792156862745098 0.819607843137255 0.933333333333333 1" />
      </material>
    </visual>
    <collision>
      <origin
        xyz="0 0 0"
        rpy="0 0 0" />
      <geometry>
        <mesh
          filename="package://basic_amr/meshes/swivel_BL.STL" />
      </geometry>
    </collision>
  </link>
  <joint
    name="swivel_BL_hinge"
    type="continuous">
    <origin
      xyz="-0.1605 -0.2495 -0.072"
      rpy="0 0 0" />
    <parent
      link="base_link" />
    <child
      link="swivel_BL" />
    <axis
      xyz="0 0 1" />
  </joint>
  <link
    name="castor_BL">
    <inertial>
      <origin
        xyz="0 -2.77555756156289E-17 2.77555756156289E-17"
        rpy="0 0 0" />
      <mass
        value="0.161396093614819" />
      <inertia
        ixx="0.000220513659227019"
        ixy="-1.49421772761313E-20"
        ixz="2.10740569971165E-19"
        iyy="0.000220513659227019"
        iyz="-1.42130425962705E-18"
        izz="0.000416796707486865" />
    </inertial>
    <visual>
      <origin
        xyz="0 0 0"
        rpy="0 0 0" />
      <geometry>
        <mesh
          filename="package://basic_amr/meshes/castor_BL.STL" />
      </geometry>
      <material
        name="">
        <color
          rgba="0.792156862745098 0.819607843137255 0.933333333333333 1" />
      </material>
    </visual>
    <collision>
      <origin
        xyz="0 0 0"
        rpy="0 0 0" />
      <geometry>
        <mesh
          filename="package://basic_amr/meshes/castor_BL.STL" />
      </geometry>
    </collision>
  </link>
  <joint
    name="castor_BL_hinge"
    type="continuous">
    <origin
      xyz="-0.001 -0.042038 -0.081558"
      rpy="1.5708 0 1.5708" />
    <parent
      link="swivel_BL" />
    <child
      link="castor_BL" />
    <axis
      xyz="0 0 -1" />
  </joint>
</robot>