<?xml version="1.0" encoding="utf-8"?>
<!-- This URDF was automatically created by SolidWorks to URDF Exporter! Originally created by Stephen Brawner (brawner@gmail.com) 
     Commit Version: 1.6.0-4-g7f85cfe  Build Version: 1.6.7995.38578
     For more information, please see http://wiki.ros.org/sw_urdf_exporter -->
<robot
  name="basic_amr">
  <link
    name="base_link">
    <inertial>
      <origin
        xyz="5.63544150454179E-06 0.0585613447753292 -0.0614713657844919"
        rpy="0 0 0" />
      <mass
        value="4.45218985232546" />
      <inertia
        ixx="0.066816643851739"
        ixy="2.67754716416141E-08"
        ixz="-1.88375583896351E-07"
        iyy="0.0777035053703119"
        iyz="2.79926678789631E-06"
        izz="0.143829093805578" />
    </inertial>
    <visual>
      <origin
        xyz="0 0 0"
        rpy="0 0 0" />
      <geometry>
        <mesh
          filename="package://basic_amr/meshes/base_link.STL" />
      </geometry>
      <material
        name="">
        <color
          rgba="0.792156862745098 0.819607843137255 0.933333333333333 1" />
      </material>
    </visual>
    <collision>
      <origin
        xyz="0 0 0"
        rpy="0 0 0" />
      <geometry>
        <mesh
          filename="package://basic_amr/meshes/base_link.STL" />
      </geometry>
    </collision>
  </link>
  <link
    name="right_wheel">
    <inertial>
      <origin
        xyz="-8.8267780932878E-08 1.8768321230489E-08 -1.07619964537509E-05"
        rpy="0 0 0" />
      <mass
        value="0.671865219229547" />
      <inertia
        ixx="0.00152382830265562"
        ixy="-2.9841396079098E-09"
        ixz="7.07941783231472E-10"
        iyy="0.00152383789327469"
        iyz="-3.46928687263826E-10"
        izz="0.00291423163667509" />
    </inertial>
    <visual>
      <origin
        xyz="0 0 0"
        rpy="0 0 0" />
      <geometry>
        <mesh
          filename="package://basic_amr/meshes/right_wheel.STL" />
      </geometry>
      <material
        name="">
        <color
          rgba="0.792156862745098 0.819607843137255 0.933333333333333 1" />
      </material>
    </visual>
    <collision>
      <origin
        xyz="0 0 0"
        rpy="0 0 0" />
      <geometry>
        <mesh
          filename="package://basic_amr/meshes/right_wheel.STL" />
      </geometry>
    </collision>
  </link>
  <joint
    name="right_wheel_hinge"
    type="continuous">
    <origin
      xyz="0.223100000000008 0 -0.131250000000001"
      rpy="1.5707963267949 0 1.5707963267949" />
    <parent
      link="base_link" />
    <child
      link="right_wheel" />
    <axis
      xyz="0 0 -1" />
  </joint>
  <link
    name="left_wheel">
    <inertial>
      <origin
        xyz="-7.44125832341513E-08 5.10511359869396E-08 -1.07619964536676E-05"
        rpy="0 0 0" />
      <mass
        value="0.671865219229546" />
      <inertia
        ixx="0.00152382759476079"
        ixy="1.2707574656377E-09"
        ixz="5.21822709264027E-10"
        iyy="0.00152383860116951"
        iyz="-5.90967101406177E-10"
        izz="0.00291423163667508" />
    </inertial>
    <visual>
      <origin
        xyz="0 0 0"
        rpy="0 0 0" />
      <geometry>
        <mesh
          filename="package://basic_amr/meshes/left_wheel.STL" />
      </geometry>
      <material
        name="">
        <color
          rgba="0.792156862745098 0.819607843137255 0.933333333333333 1" />
      </material>
    </visual>
    <collision>
      <origin
        xyz="0 0 0"
        rpy="0 0 0" />
      <geometry>
        <mesh
          filename="package://basic_amr/meshes/left_wheel.STL" />
      </geometry>
    </collision>
  </link>
  <joint
    name="left_wheel_hinge"
    type="continuous">
    <origin
      xyz="-0.223099999999996 0 -0.13125"
      rpy="3.14159265358979 -1.5707963267949 0" />
    <parent
      link="base_link" />
    <child
      link="left_wheel" />
    <axis
      xyz="0 0 -1" />
  </joint>
  <link
    name="swivel_FR">
    <inertial>
      <origin
        xyz="2.10863983640674E-06 -0.0155772535469802 -0.026224650737631"
        rpy="0 0 0" />
      <mass
        value="0.0401879953591251" />
      <inertia
        ixx="4.73228658677592E-05"
        ixy="-6.88516059281353E-10"
        ixz="-4.43687198765333E-10"
        iyy="5.06898250760734E-05"
        iyz="-1.06656202531615E-05"
        izz="4.82017926993399E-05" />
    </inertial>
    <visual>
      <origin
        xyz="0 0 0"
        rpy="0 0 0" />
      <geometry>
        <mesh
          filename="package://basic_amr/meshes/swivel_FR.STL" />
      </geometry>
      <material
        name="">
        <color
          rgba="0.792156862745098 0.819607843137255 0.933333333333333 1" />
      </material>
    </visual>
    <collision>
      <origin
        xyz="0 0 0"
        rpy="0 0 0" />
      <geometry>
        <mesh
          filename="package://basic_amr/meshes/swivel_FR.STL" />
      </geometry>
    </collision>
  </link>
  <joint
    name="swivel_FR_hinge"
    type="continuous">
    <origin
      xyz="0.163000000000006 0.250500000000009 -0.0720000000000007"
      rpy="0 0 0" />
    <parent
      link="base_link" />
    <child
      link="swivel_FR" />
    <axis
      xyz="0 0 1" />
  </joint>
  <link
    name="castor_FR">
    <inertial>
      <origin
        xyz="-5.55111512312578E-17 0 -5.55111512312578E-17"
        rpy="0 0 0" />
      <mass
        value="0.16139609361482" />
      <inertia
        ixx="0.00022051365922702"
        ixy="-1.41172157876538E-22"
        ixz="-6.7256767728707E-19"
        iyy="0.00022051365922702"
        iyz="2.54804746356287E-19"
        izz="0.000416796707486866" />
    </inertial>
    <visual>
      <origin
        xyz="0 0 0"
        rpy="0 0 0" />
      <geometry>
        <mesh
          filename="package://basic_amr/meshes/castor_FR.STL" />
      </geometry>
      <material
        name="">
        <color
          rgba="0.792156862745098 0.819607843137255 0.933333333333333 1" />
      </material>
    </visual>
    <collision>
      <origin
        xyz="0 0 0"
        rpy="0 0 0" />
      <geometry>
        <mesh
          filename="package://basic_amr/meshes/castor_FR.STL" />
      </geometry>
    </collision>
  </link>
  <joint
    name="castor_FR_hinge"
    type="continuous">
    <origin
      xyz="0.00100000000000061 -0.0420254389561369 -0.0825575197240634"
      rpy="1.5707963267949 0 1.5707963267949" />
    <parent
      link="swivel_FR" />
    <child
      link="castor_FR" />
    <axis
      xyz="0 0 1" />
  </joint>
  <link
    name="swivel_FL">
    <inertial>
      <origin
        xyz="2.10863983640674E-06 -0.0155772535469801 -0.0262246507376314"
        rpy="0 0 0" />
      <mass
        value="0.0401879953591256" />
      <inertia
        ixx="4.73228658677601E-05"
        ixy="-6.8851605932601E-10"
        ixz="-4.43687198738119E-10"
        iyy="5.06898250760746E-05"
        iyz="-1.06656202531615E-05"
        izz="4.82017926993412E-05" />
    </inertial>
    <visual>
      <origin
        xyz="0 0 0"
        rpy="0 0 0" />
      <geometry>
        <mesh
          filename="package://basic_amr/meshes/swivel_FL.STL" />
      </geometry>
      <material
        name="">
        <color
          rgba="0.792156862745098 0.819607843137255 0.933333333333333 1" />
      </material>
    </visual>
    <collision>
      <origin
        xyz="0 0 0"
        rpy="0 0 0" />
      <geometry>
        <mesh
          filename="package://basic_amr/meshes/swivel_FL.STL" />
      </geometry>
    </collision>
  </link>
  <joint
    name="swivel_FL_hinge"
    type="continuous">
    <origin
      xyz="-0.161999999999997 0.250499999999997 -0.0720000000000005"
      rpy="0 0 0" />
    <parent
      link="base_link" />
    <child
      link="swivel_FL" />
    <axis
      xyz="0 0 1" />
  </joint>
  <link
    name="castor_FL">
    <inertial>
      <origin
        xyz="2.77555756156289E-17 0 -5.55111512312578E-17"
        rpy="0 0 0" />
      <mass
        value="0.16139609361482" />
      <inertia
        ixx="0.000220513659227019"
        ixy="5.07634251736565E-20"
        ixz="1.65398740429508E-19"
        iyy="0.000220513659227019"
        iyz="-1.28760076892778E-18"
        izz="0.000416796707486866" />
    </inertial>
    <visual>
      <origin
        xyz="0 0 0"
        rpy="0 0 0" />
      <geometry>
        <mesh
          filename="package://basic_amr/meshes/castor_FL.STL" />
      </geometry>
      <material
        name="">
        <color
          rgba="0.792156862745098 0.819607843137255 0.933333333333333 1" />
      </material>
    </visual>
    <collision>
      <origin
        xyz="0 0 0"
        rpy="0 0 0" />
      <geometry>
        <mesh
          filename="package://basic_amr/meshes/castor_FL.STL" />
      </geometry>
    </collision>
  </link>
  <joint
    name="castor_FL_hinge"
    type="continuous">
    <origin
      xyz="0.000999999999999168 -0.042025438956134 -0.0825575197240596"
      rpy="1.5707963267949 0 1.5707963267949" />
    <parent
      link="swivel_FL" />
    <child
      link="castor_FL" />
    <axis
      xyz="0 0 1" />
  </joint>
  <link
    name="swivel_BR">
    <inertial>
      <origin
        xyz="2.10863983624021E-06 -0.01557725354698 -0.0262246507376313"
        rpy="0 0 0" />
      <mass
        value="0.0401879953591256" />
      <inertia
        ixx="4.73228658677596E-05"
        ixy="-6.88516059539087E-10"
        ixz="-4.43687198680298E-10"
        iyy="5.06898250760743E-05"
        iyz="-1.06656202531614E-05"
        izz="4.82017926993408E-05" />
    </inertial>
    <visual>
      <origin
        xyz="0 0 0"
        rpy="0 0 0" />
      <geometry>
        <mesh
          filename="package://basic_amr/meshes/swivel_BR.STL" />
      </geometry>
      <material
        name="">
        <color
          rgba="0.792156862745098 0.819607843137255 0.933333333333333 1" />
      </material>
    </visual>
    <collision>
      <origin
        xyz="0 0 0"
        rpy="0 0 0" />
      <geometry>
        <mesh
          filename="package://basic_amr/meshes/swivel_BR.STL" />
      </geometry>
    </collision>
  </link>
  <joint
    name="swivel_BR_hinge"
    type="continuous">
    <origin
      xyz="0.160499999999998 -0.249499999999981 -0.0719999999999989"
      rpy="0 0 0" />
    <parent
      link="base_link" />
    <child
      link="swivel_BR" />
    <axis
      xyz="0 0 1" />
  </joint>
  <link
    name="castor_BR">
    <inertial>
      <origin
        xyz="0 0 -2.77555756156289E-17"
        rpy="0 0 0" />
      <mass
        value="0.16139609361482" />
      <inertia
        ixx="0.00022051365922702"
        ixy="-1.34502770036554E-20"
        ixz="2.25234764169812E-19"
        iyy="0.00022051365922702"
        iyz="-1.38972427372641E-18"
        izz="0.000416796707486866" />
    </inertial>
    <visual>
      <origin
        xyz="0 0 0"
        rpy="0 0 0" />
      <geometry>
        <mesh
          filename="package://basic_amr/meshes/castor_BR.STL" />
      </geometry>
      <material
        name="">
        <color
          rgba="0.792156862745098 0.819607843137255 0.933333333333333 1" />
      </material>
    </visual>
    <collision>
      <origin
        xyz="0 0 0"
        rpy="0 0 0" />
      <geometry>
        <mesh
          filename="package://basic_amr/meshes/castor_BR.STL" />
      </geometry>
    </collision>
  </link>
  <joint
    name="castor_BR_hinge"
    type="continuous">
    <origin
      xyz="0.000999999999999668 -0.0420254389561336 -0.0825575197240624"
      rpy="1.5707963267949 0 1.5707963267949" />
    <parent
      link="swivel_BR" />
    <child
      link="castor_BR" />
    <axis
      xyz="0 0 1" />
  </joint>
  <link
    name="swivel_BL">
    <inertial>
      <origin
        xyz="2.10863983632348E-06 -0.0155772535469802 -0.0262246507376309"
        rpy="0 0 0" />
      <mass
        value="0.0401879953591248" />
      <inertia
        ixx="4.7322865867759E-05"
        ixy="-6.88516059010064E-10"
        ixz="-4.43687198871794E-10"
        iyy="5.06898250760744E-05"
        iyz="-1.06656202531614E-05"
        izz="4.82017926993406E-05" />
    </inertial>
    <visual>
      <origin
        xyz="0 0 0"
        rpy="0 0 0" />
      <geometry>
        <mesh
          filename="package://basic_amr/meshes/swivel_BL.STL" />
      </geometry>
      <material
        name="">
        <color
          rgba="0.792156862745098 0.819607843137255 0.933333333333333 1" />
      </material>
    </visual>
    <collision>
      <origin
        xyz="0 0 0"
        rpy="0 0 0" />
      <geometry>
        <mesh
          filename="package://basic_amr/meshes/swivel_BL.STL" />
      </geometry>
    </collision>
  </link>
  <joint
    name="swivel_BL_hinge"
    type="continuous">
    <origin
      xyz="-0.160500000000002 -0.249499999999982 -0.0719999999999989"
      rpy="0 0 0" />
    <parent
      link="base_link" />
    <child
      link="swivel_BL" />
    <axis
      xyz="0 0 1" />
  </joint>
  <link
    name="castor_BL">
    <inertial>
      <origin
        xyz="0 -2.77555756156289E-17 2.77555756156289E-17"
        rpy="0 0 0" />
      <mass
        value="0.161396093614819" />
      <inertia
        ixx="0.000220513659227019"
        ixy="-1.49421772761313E-20"
        ixz="2.10740569971164E-19"
        iyy="0.000220513659227019"
        iyz="-1.42130425962705E-18"
        izz="0.000416796707486866" />
    </inertial>
    <visual>
      <origin
        xyz="0 0 0"
        rpy="0 0 0" />
      <geometry>
        <mesh
          filename="package://basic_amr/meshes/castor_BL.STL" />
      </geometry>
      <material
        name="">
        <color
          rgba="0.792156862745098 0.819607843137255 0.933333333333333 1" />
      </material>
    </visual>
    <collision>
      <origin
        xyz="0 0 0"
        rpy="0 0 0" />
      <geometry>
        <mesh
          filename="package://basic_amr/meshes/castor_BL.STL" />
      </geometry>
    </collision>
  </link>
  <joint
    name="castor_BL_hinge"
    type="continuous">
    <origin
      xyz="-0.00100000000000036 -0.0420254389561341 -0.0825575197240612"
      rpy="1.5707963267949 0 1.5707963267949" />
    <parent
      link="swivel_BL" />
    <child
      link="castor_BL" />
    <axis
      xyz="0 0 -1" />
  </joint>
</robot>