<?xml version="1.0" encoding="utf-8"?>
<!-- This URDF was automatically created by SolidWorks to URDF Exporter! Originally created by Stephen Brawner (brawner@gmail.com)
     Commit Version: 1.6.0-4-g7f85cfe  Build Version: 1.6.7995.38578
     For more information, please see http://wiki.ros.org/sw_urdf_exporter -->
<robot
  name="full_amr_sensor">
  <link
    name="base_link_true">
    <inertial>
      <origin
        xyz="4.39643166750005E-07 0.0677968819277461 -0.0609502708124765"
        rpy="0 0 0" />
      <mass
        value="3.86321584157732" />
      <inertia
        ixx="0.066007396363459"
        ixy="2.41600659459608E-08"
        ixz="-3.29972385417551E-08"
        iyy="0.0766853600125674"
        iyz="1.25967847791009E-07"
        izz="0.142096939827593" />
    </inertial>
    <visual>
      <origin
        xyz="0 0 0"
        rpy="0 0 0" />
      <geometry>
        <mesh
          filename="package://full_amr_sensor/meshes/base_link.STL" />
      </geometry>
      <material
        name="">
        <color
          rgba="0.792156862745098 0.819607843137255 0.933333333333333 1" />
      </material>
    </visual>
    <collision>
      <origin
        xyz="0 0 0"
        rpy="0 0 0" />
      <geometry>
        <mesh
          filename="package://full_amr_sensor/meshes/base_link.STL" />
      </geometry>
    </collision>
  </link>
  <link
    name="right_pivot">
    <inertial>
      <origin
        xyz="6.72247923302338E-05 0.0422607120673676 0.0142964039825725"
        rpy="0 0 0" />
      <mass
        value="0.17398061104375" />
      <inertia
        ixx="0.00035672283065886"
        ixy="8.00213179277125E-10"
        ixz="-7.76960584308333E-08"
        iyy="6.87085895055142E-05"
        iyz="3.41669974501659E-06"
        izz="0.000387113090933446" />
    </inertial>
    <visual>
      <origin
        xyz="0 0 0"
        rpy="0 0 0" />
      <geometry>
        <mesh
          filename="package://full_amr_sensor/meshes/right_pivot.STL" />
      </geometry>
      <material
        name="">
        <color
          rgba="0.792156862745098 0.819607843137255 0.933333333333333 1" />
      </material>
    </visual>
    <collision>
      <origin
        xyz="0 0 0"
        rpy="0 0 0" />
      <geometry>
        <mesh
          filename="package://full_amr_sensor/meshes/right_pivot.STL" />
      </geometry>
    </collision>
  </link>
  <joint
    name="right_pivot_hinge"
    type="continuous">
    <origin
      xyz="0.162500000000008 0.127500000000012 -0.0809999999999999"
      rpy="0 0 0" />
    <parent
      link="base_link_true" />
    <child
      link="right_pivot" />
    <axis
      xyz="1 0 0" />
  </joint>
  <link
    name="right_wheel">
    <inertial>
      <origin
        xyz="8.82920752575105E-08 -1.86536986135355E-08 -1.07619964537509E-05"
        rpy="0 0 0" />
      <mass
        value="0.671865219229547" />
      <inertia
        ixx="0.00152382831042098"
        ixy="-2.99658197526883E-09"
        ixz="-7.08391619227813E-10"
        iyy="0.00152383788550933"
        iyz="3.46009207208031E-10"
        izz="0.00291423163667508" />
    </inertial>
    <visual>
      <origin
        xyz="0 0 0"
        rpy="0 0 0" />
      <geometry>
        <mesh
          filename="package://full_amr_sensor/meshes/right_wheel.STL" />
      </geometry>
      <material
        name="">
        <color
          rgba="0.792156862745098 0.819607843137255 0.933333333333333 1" />
      </material>
    </visual>
    <collision>
      <origin
        xyz="0 0 0"
        rpy="0 0 0" />
      <geometry>
        <mesh
          filename="package://full_amr_sensor/meshes/right_wheel.STL" />
      </geometry>
    </collision>
  </link>
  <joint
    name="right_wheel_hinge"
    type="continuous">
    <origin
      xyz="0.060600000000002 -0.127825510601864 -0.0494161040489112"
      rpy="1.5707963267949 0 1.5707963267949" />
    <parent
      link="right_pivot" />
    <child
      link="right_wheel" />
    <axis
      xyz="0 0 -1" />
  </joint>
  <link
    name="FR_swivel">
    <inertial>
      <origin
        xyz="2.10136369049874E-06 -0.0158449037086422 -0.0263178294256963"
        rpy="0 0 0" />
      <mass
        value="0.0403331792084209" />
      <inertia
        ixx="4.78544962729301E-05"
        ixy="-6.90281179873479E-10"
        ixz="-4.45519404666891E-10"
        iyy="5.10623960568997E-05"
        iyz="-1.08916975241884E-05"
        izz="4.85318020084122E-05" />
    </inertial>
    <visual>
      <origin
        xyz="0 0 0"
        rpy="0 0 0" />
      <geometry>
        <mesh
          filename="package://full_amr_sensor/meshes/FR_swivel.STL" />
      </geometry>
      <material
        name="">
        <color
          rgba="0.792156862745098 0.819607843137255 0.933333333333333 1" />
      </material>
    </visual>
    <collision>
      <origin
        xyz="0 0 0"
        rpy="0 0 0" />
      <geometry>
        <mesh
          filename="package://full_amr_sensor/meshes/FR_swivel.STL" />
      </geometry>
    </collision>
  </link>
  <joint
    name="FR_swivel_hinge"
    type="continuous">
    <origin
      xyz="0.000499999999999584 0.123056163560861 0.00819637783921516"
      rpy="0 0 0" />
    <parent
      link="right_pivot" />
    <child
      link="FR_swivel" />
    <axis
      xyz="0 0.00653195251969943 0.999978666570583" />
  </joint>
  <link
    name="FR_castor">
    <inertial>
      <origin
        xyz="2.16493489801906E-14 -1.02695629777827E-15 1.89570581454745E-14"
        rpy="0 0 0" />
      <mass
        value="0.16139609361482" />
      <inertia
        ixx="0.000416796707486866"
        ixy="2.74122864771026E-18"
        ixz="-6.94955623862298E-19"
        iyy="0.000220513659227019"
        iyz="2.82673068694294E-20"
        izz="0.000220513659227019" />
    </inertial>
    <visual>
      <origin
        xyz="0 0 0"
        rpy="0 0 0" />
      <geometry>
        <mesh
          filename="package://full_amr_sensor/meshes/FR_castor.STL" />
      </geometry>
      <material
        name="">
        <color
          rgba="0.792156862745098 0.819607843137255 0.933333333333333 1" />
      </material>
    </visual>
    <collision>
      <origin
        xyz="0 0 0"
        rpy="0 0 0" />
      <geometry>
        <mesh
          filename="package://full_amr_sensor/meshes/FR_castor.STL" />
      </geometry>
    </collision>
  </link>
  <joint
    name="FR_castor_hinge"
    type="continuous">
    <origin
      xyz="0.00099999999997849 -0.0425510539838774 -0.0842238553194065"
      rpy="0 0 0" />
    <parent
      link="FR_swivel" />
    <child
      link="FR_castor" />
    <axis
      xyz="1 0 0" />
  </joint>
  <link
    name="left_pivot">
    <inertial>
      <origin
        xyz="6.72247985100405E-05 0.0421520181325834 0.0146137713653624"
        rpy="0 0 0" />
      <mass
        value="0.173980611061865" />
      <inertia
        ixx="0.000356722830492718"
        ixy="1.38441365791901E-09"
        ixz="-7.76878439844702E-08"
        iyy="6.86752111533773E-05"
        iyz="1.0221976196466E-06"
        izz="0.000387146469119926" />
    </inertial>
    <visual>
      <origin
        xyz="0 0 0"
        rpy="0 0 0" />
      <geometry>
        <mesh
          filename="package://full_amr_sensor/meshes/left_pivot.STL" />
      </geometry>
      <material
        name="">
        <color
          rgba="0.792156862745098 0.819607843137255 0.933333333333333 1" />
      </material>
    </visual>
    <collision>
      <origin
        xyz="0 0 0"
        rpy="0 0 0" />
      <geometry>
        <mesh
          filename="package://full_amr_sensor/meshes/left_pivot.STL" />
      </geometry>
    </collision>
  </link>
  <joint
    name="left_pivot_hinge"
    type="continuous">
    <origin
      xyz="-0.162500000000001 0.12749999999999 -0.081"
      rpy="0 0 0" />
    <parent
      link="base_link_true" />
    <child
      link="left_pivot" />
    <axis
      xyz="1 0 0" />
  </joint>
  <link
    name="left_wheel">
    <inertial>
      <origin
        xyz="5.10511359852472E-08 7.44125832254371E-08 -1.07619964537509E-05"
        rpy="0 0 0" />
      <mass
        value="0.671865219229547" />
      <inertia
        ixx="0.00152383860116951"
        ixy="-1.27075746545259E-09"
        ixz="-5.90967111162249E-10"
        iyy="0.00152382759476079"
        iyz="-5.21822709935788E-10"
        izz="0.00291423163667508" />
    </inertial>
    <visual>
      <origin
        xyz="0 0 0"
        rpy="0 0 0" />
      <geometry>
        <mesh
          filename="package://full_amr_sensor/meshes/left_wheel.STL" />
      </geometry>
      <material
        name="">
        <color
          rgba="0.792156862745098 0.819607843137255 0.933333333333333 1" />
      </material>
    </visual>
    <collision>
      <origin
        xyz="0 0 0"
        rpy="0 0 0" />
      <geometry>
        <mesh
          filename="package://full_amr_sensor/meshes/left_wheel.STL" />
      </geometry>
    </collision>
  </link>
  <joint
    name="left_wheel_hinge"
    type="continuous">
    <origin
      xyz="-0.0606000000000003 -0.127450321712043 -0.050375867193494"
      rpy="3.14159265358979 -1.5707963267949 0" />
    <parent
      link="left_pivot" />
    <child
      link="left_wheel" />
    <axis
      xyz="0 0 -1" />
  </joint>
  <link
    name="FL_swivel">
    <inertial>
      <origin
        xyz="6.55117784613135E-05 -0.0156463149501383 -0.0264362233956825"
        rpy="0 0 0" />
      <mass
        value="0.0403332363730702" />
      <inertia
        ixx="4.78543933221479E-05"
        ixy="-1.42826551761243E-08"
        ixz="4.35430090192042E-08"
        iyy="5.12258920158362E-05"
        iyz="-1.08712913722346E-05"
        izz="4.83681025928455E-05" />
    </inertial>
    <visual>
      <origin
        xyz="0 0 0"
        rpy="0 0 0" />
      <geometry>
        <mesh
          filename="package://full_amr_sensor/meshes/FL_swivel.STL" />
      </geometry>
      <material
        name="">
        <color
          rgba="0.792156862745098 0.819607843137255 0.933333333333333 1" />
      </material>
    </visual>
    <collision>
      <origin
        xyz="0 0 0"
        rpy="0 0 0" />
      <geometry>
        <mesh
          filename="package://full_amr_sensor/meshes/FL_swivel.STL" />
      </geometry>
    </collision>
  </link>
  <joint
    name="FL_swivel_hinge"
    type="continuous">
    <origin
      xyz="0.000499999999999945 0.122991053569608 0.00912144406537516"
      rpy="0 0 0" />
    <parent
      link="left_pivot" />
    <child
      link="FL_swivel" />
    <axis
      xyz="0 -0.000987385793199488 0.999999512534529" />
  </joint>
  <link
    name="FL_castor">
    <inertial>
      <origin
        xyz="-2.77555756156289E-17 -2.77555756156289E-17 -5.55111512312578E-17"
        rpy="0 0 0" />
      <mass
        value="0.161396093614819" />
      <inertia
        ixx="0.000416793494356327"
        ixy="7.94148674684215E-07"
        ixz="7.8413150140276E-10"
        iyy="0.000220516872354425"
        iyz="3.17259785973721E-12"
        izz="0.000220513659230152" />
    </inertial>
    <visual>
      <origin
        xyz="0 0 0"
        rpy="0 0 0" />
      <geometry>
        <mesh
          filename="package://full_amr_sensor/meshes/FL_castor.STL" />
      </geometry>
      <material
        name="">
        <color
          rgba="0.792156862745098 0.819607843137255 0.933333333333333 1" />
      </material>
    </visual>
    <collision>
      <origin
        xyz="0 0 0"
        rpy="0 0 0" />
      <geometry>
        <mesh
          filename="package://full_amr_sensor/meshes/FL_castor.STL" />
      </geometry>
    </collision>
  </link>
  <joint
    name="FL_castor_hinge"
    type="continuous">
    <origin
      xyz="-0.000830061024273993 -0.0419202476273774 -0.0845414326679843"
      rpy="0 0 0" />
    <parent
      link="FL_swivel" />
    <child
      link="FL_castor" />
    <axis
      xyz="0.999991815024994 0.00404596923608611 0" />
  </joint>
  <link
    name="back_pivot">
    <inertial>
      <origin
        xyz="2.77517345254814E-17 0.000116576900137055 0.0183318680820081"
        rpy="0 0 0" />
      <mass
        value="0.241012788592429" />
      <inertia
        ixx="9.580182683753E-05"
        ixy="-3.46230016315995E-20"
        ixz="-5.99745653785195E-21"
        iyy="0.000880790277251447"
        iyz="4.99589834640678E-21"
        izz="0.000957865697471465" />
    </inertial>
    <visual>
      <origin
        xyz="0 0 0"
        rpy="0 0 0" />
      <geometry>
        <mesh
          filename="package://full_amr_sensor/meshes/back_pivot.STL" />
      </geometry>
      <material
        name="">
        <color
          rgba="0.792156862745098 0.819607843137255 0.933333333333333 1" />
      </material>
    </visual>
    <collision>
      <origin
        xyz="0 0 0"
        rpy="0 0 0" />
      <geometry>
        <mesh
          filename="package://full_amr_sensor/meshes/back_pivot.STL" />
      </geometry>
    </collision>
  </link>
  <joint
    name="back_pivot_hinge"
    type="continuous">
    <origin
      xyz="0 -0.24999999999999 -0.0810000000000002"
      rpy="0 0 0" />
    <parent
      link="base_link_true" />
    <child
      link="back_pivot" />
    <axis
      xyz="0 -1 0" />
  </joint>
  <link
    name="BR_swivel">
    <inertial>
      <origin
        xyz="-2.86806979955812E-05 -0.0156725402272886 -0.0264207636386581"
        rpy="0 0 0" />
      <mass
        value="0.0403332273268806" />
      <inertia
        ixx="4.78543953407379E-05"
        ixy="5.89296547468749E-09"
        ixz="-2.17988033710917E-08"
        iyy="5.1204498132695E-05"
        iyz="-1.08741782741284E-05"
        izz="4.83895899094599E-05" />
    </inertial>
    <visual>
      <origin
        xyz="0 0 0"
        rpy="0 0 0" />
      <geometry>
        <mesh
          filename="package://full_amr_sensor/meshes/BR_swivel.STL" />
      </geometry>
      <material
        name="">
        <color
          rgba="0.792156862745098 0.819607843137255 0.933333333333333 1" />
      </material>
    </visual>
    <collision>
      <origin
        xyz="0 0 0"
        rpy="0 0 0" />
      <geometry>
        <mesh
          filename="package://full_amr_sensor/meshes/BR_swivel.STL" />
      </geometry>
    </collision>
  </link>
  <joint
    name="BR_swivel_hinge"
    type="continuous">
    <origin
      xyz="0.160500000000001 0.000500000000000667 0.00899999999999893"
      rpy="0 0 0" />
    <parent
      link="back_pivot" />
    <child
      link="BR_swivel" />
    <axis
      xyz="0 0 1" />
  </joint>
  <link
    name="BR_castor">
    <inertial>
      <origin
        xyz="7.49400541621981E-16 2.22044604925031E-16 -3.05311331771918E-16"
        rpy="0 0 0" />
      <mass
        value="0.16139609361482" />
      <inertia
        ixx="0.000416795950313433"
        ixy="-3.8551230350754E-07"
        ixz="-1.29586487622583E-18"
        iyy="0.000220514416400453"
        iyz="1.12161980613364E-20"
        izz="0.000220513659227019" />
    </inertial>
    <visual>
      <origin
        xyz="0 0 0"
        rpy="0 0 0" />
      <geometry>
        <mesh
          filename="package://full_amr_sensor/meshes/BR_castor.STL" />
      </geometry>
      <material
        name="">
        <color
          rgba="0.792156862745098 0.819607843137255 0.933333333333333 1" />
      </material>
    </visual>
    <collision>
      <origin
        xyz="0 0 0"
        rpy="0 0 0" />
      <geometry>
        <mesh
          filename="package://full_amr_sensor/meshes/BR_castor.STL" />
      </geometry>
    </collision>
  </link>
  <joint
    name="BR_castor_hinge"
    type="continuous">
    <origin
      xyz="0.000917507259500183 -0.0420018830581295 -0.0844999999999997"
      rpy="0 0 0" />
    <parent
      link="BR_swivel" />
    <child
      link="BR_castor" />
    <axis
      xyz="-0.999998071218656 0.00196406694564723 0" />
  </joint>
  <link
    name="BL_swivel">
    <inertial>
      <origin
        xyz="-8.23621583788681E-05 -0.0156723375221494 -0.0264207621674671"
        rpy="0 0 0" />
      <mass
        value="0.040333232832404" />
      <inertia
        ixx="4.7854441195365E-05"
        ixy="1.73687216368099E-08"
        ixz="-5.90443392248014E-08"
        iyy="5.12044011536031E-05"
        iyz="-1.08740264445735E-05"
        izz="4.83895789718874E-05" />
    </inertial>
    <visual>
      <origin
        xyz="0 0 0"
        rpy="0 0 0" />
      <geometry>
        <mesh
          filename="package://full_amr_sensor/meshes/BL_swivel.STL" />
      </geometry>
      <material
        name="">
        <color
          rgba="0.792156862745098 0.819607843137255 0.933333333333333 1" />
      </material>
    </visual>
    <collision>
      <origin
        xyz="0 0 0"
        rpy="0 0 0" />
      <geometry>
        <mesh
          filename="package://full_amr_sensor/meshes/BL_swivel.STL" />
      </geometry>
    </collision>
  </link>
  <joint
    name="BL_swivel_hinge"
    type="continuous">
    <origin
      xyz="-0.160499999999999 0.000499999999999445 0.00900000000000113"
      rpy="0 0 0" />
    <parent
      link="back_pivot" />
    <child
      link="BL_swivel" />
    <axis
      xyz="0 0 1" />
  </joint>
  <link
    name="BL_castor">
    <inertial>
      <origin
        xyz="6.93889390390723E-16 -6.66133814775094E-16 0"
        rpy="0 0 0" />
      <mass
        value="0.16139609361482" />
      <inertia
        ixx="0.000416791006545238"
        ixy="-1.05781175070597E-06"
        ixz="-1.29869302140369E-18"
        iyy="0.000220519360168647"
        iyz="8.65420256291731E-23"
        izz="0.000220513659227019" />
    </inertial>
    <visual>
      <origin
        xyz="0 0 0"
        rpy="0 0 0" />
      <geometry>
        <mesh
          filename="package://full_amr_sensor/meshes/BL_castor.STL" />
      </geometry>
      <material
        name="">
        <color
          rgba="0.792156862745098 0.819607843137255 0.933333333333333 1" />
      </material>
    </visual>
    <collision>
      <origin
        xyz="0 0 0"
        rpy="0 0 0" />
      <geometry>
        <mesh
          filename="package://full_amr_sensor/meshes/BL_castor.STL" />
      </geometry>
    </collision>
  </link>
  <joint
    name="BL_castor_hinge"
    type="continuous">
    <origin
      xyz="-0.00122633583817874 -0.0419940007669185 -0.0845"
      rpy="0 0 0" />
    <parent
      link="BL_swivel" />
    <child
      link="BL_castor" />
    <axis
      xyz="-0.999985477648034 0.00538929429831941 0" />
  </joint>
  <link
    name="zed2">
    <inertial>
      <origin
        xyz="-0.00111518039315167 -0.0600009977385601 4.53380794620262E-05"
        rpy="0 0 0" />
      <mass
        value="0.152262285698166" />
      <inertia
        ixx="0.000372345846956899"
        ixy="2.30540794654782E-09"
        ixz="4.79189971081129E-08"
        iyy="2.28049149180012E-05"
        iyz="4.81653407642373E-10"
        izz="0.000374775131146336" />
    </inertial>
    <visual>
      <origin
        xyz="0 0 0"
        rpy="0 0 0" />
      <geometry>
        <mesh
          filename="package://full_amr_sensor/meshes/zed2.STL" />
      </geometry>
      <material
        name="">
        <color
          rgba="0.792156862745098 0.819607843137255 0.933333333333333 1" />
      </material>
    </visual>
    <collision>
      <origin
        xyz="0 0 0"
        rpy="0 0 0" />
      <geometry>
        <mesh
          filename="package://full_amr_sensor/meshes/zed2.STL" />
      </geometry>
    </collision>
  </link>
  <joint
    name="zed2_hinge"
    type="fixed">
    <origin
      xyz="-0.081402 0.37212 -0.090184"
      rpy="0 0 1.5708" />
    <parent
      link="base_link_true" />
    <child
      link="zed2" />
    <axis
      xyz="0 0 0" />
  </joint>
  <link
    name="base_link">
    <inertial>
      <origin
        xyz="2.60208521396521E-18 0 -0.006"
        rpy="0 0 0" />
      <mass
        value="0.191381897465873" />
      <inertia
        ixx="0.000128572750991292"
        ixy="0"
        ixz="2.44585115803792E-36"
        iyy="0.000128572750991292"
        iyz="-3.9526587223827E-37"
        izz="7.77249731083278E-05" />
    </inertial>
    <visual>
      <origin
        xyz="0 0 0"
        rpy="0 0 0" />
      <geometry>
        <mesh
          filename="package://full_amr_sensor/meshes/m2m2.STL" />
      </geometry>
      <material
        name="">
        <color
          rgba="0.792156862745098 0.819607843137255 0.933333333333333 1" />
      </material>
    </visual>
    <collision>
      <origin
        xyz="0 0 0"
        rpy="0 0 0" />
      <geometry>
        <mesh
          filename="package://full_amr_sensor/meshes/m2m2.STL" />
      </geometry>
    </collision>
  </link>
  <joint
    name="m2m2_hinge"
    type="fixed">
    <origin
      xyz="-0.0073926 0.32076 -0.061"
      rpy="0 0 0" />
    <parent
      link="base_link_true" />
    <child
      link="base_link" />
    <axis
      xyz="0 0 0" />
  </joint>
  <link
    name="imu">
    <inertial>
      <origin
        xyz="0.0010494325786821 0.00140502202828319 0.00116672748007951"
        rpy="0 0 0" />
      <mass
        value="0.00291242008037128" />
      <inertia
        ixx="3.26750538407669E-07"
        ixy="4.34477610509117E-11"
        ixz="-6.25294405530845E-12"
        iyy="3.28268124576907E-07"
        iyz="-5.25903715021758E-12"
        izz="6.52977183322461E-07" />
    </inertial>
    <visual>
      <origin
        xyz="0 0 0"
        rpy="0 0 0" />
      <geometry>
        <mesh
          filename="package://full_amr_sensor/meshes/imu.STL" />
      </geometry>
      <material
        name="">
        <color
          rgba="1 1 1 1" />
      </material>
    </visual>
    <collision>
      <origin
        xyz="0 0 0"
        rpy="0 0 0" />
      <geometry>
        <mesh
          filename="package://full_amr_sensor/meshes/imu.STL" />
      </geometry>
    </collision>
  </link>
  <joint
    name="imu_hinge"
    type="fixed">
    <origin
      xyz="0 0.2275 -0.0981"
      rpy="3.1416 0 0" />
    <parent
      link="base_link_true" />
    <child
      link="imu" />
    <axis
      xyz="0 0 0" />
  </joint>

<!-- Please work -->
  <transmission name="left_wheel_transmission">
    <type>transmission_interface/SimpleTransmission</type>
    <joint name="left_wheel_hinge">
      <hardwareInterface>hardware_interface/VelocityJointInterface</hardwareInterface>
    </joint>
    <actuator name="left_wheel_actuator">
      <mechanicalReduction>7</mechanicalReduction>
      <hardwareInterface>VelocityJointInterface</hardwareInterface>
    </actuator>
  </transmission>

  <transmission name="right_wheel_transmission">
    <type>transmission_interface/SimpleTransmission</type>
    <joint name="right_wheel_hinge">
      <hardwareInterface>hardware_interface/VelocityJointInterface</hardwareInterface>
    </joint>
    <actuator name="right_wheel_actuator">
      <mechanicalReduction>7</mechanicalReduction>
      <hardwareInterface>VelocityJointInterface</hardwareInterface>
    </actuator>
  </transmission>

  <!-- Enable gazebo -->
  <gazebo>
    <plugin name="gazebo_ros_control" filename="libgazebo_ros_control.so">
      <robotNamespace>/</robotNamespace>
    </plugin>
  </gazebo>

  <!-- Camera -->
  <gazebo reference="zed2">
    <sensor type="camera" name="camera1">
      <update_rate>30.0</update_rate>
      <camera name="head">
        <horizontal_fov>1.3962634</horizontal_fov>
        <image>
          <width>800</width>
          <height>800</height>
          <format>R8G8B8</format>
        </image>
        <clip>
          <near>0.02</near>
          <far>300</far>
        </clip>
        <noise>
          <type>gaussian</type>
          <!-- Noise is sampled independently per pixel on each frame.
               That pixel's noise value is added to each of its color
               channels, which at that point lie in the range [0,1]. -->
          <mean>0.0</mean>
          <stddev>0.007</stddev>
        </noise>
      </camera>
      <plugin name="camera_controller" filename="libgazebo_ros_camera.so">
        <alwaysOn>true</alwaysOn>
        <updateRate>0.0</updateRate>
        <cameraName>rrbot/camera1</cameraName>
        <imageTopicName>image_raw</imageTopicName>
        <cameraInfoTopicName>camera_info</cameraInfoTopicName>
        <frameName>camera_link</frameName>
        <hackBaseline>0.07</hackBaseline>
        <distortionK1>0.0</distortionK1>
        <distortionK2>0.0</distortionK2>
        <distortionK3>0.0</distortionK3>
        <distortionT1>0.0</distortionT1>
        <distortionT2>0.0</distortionT2>
      </plugin>
    </sensor>
  </gazebo>
  <!-- Lidar -->
<<<<<<< HEAD
  <gazebo reference="base_link">
=======
  <gazebo reference="laser">
>>>>>>> 54e9c964d76de8a046ab820bedd4c2f3ef97649a
      <material>Gazebo/Red</material>

      <sensor name="laser" type="ray">
          <pose> 0 0 0 0 0 0 </pose>
          <visualize>true</visualize>
          <update_rate>10</update_rate>
          <ray>
              <scan>
                  <horizontal>
                      <samples>360</samples>
                      <min_angle>-3.14</min_angle>
                      <max_angle>3.14</max_angle>
                  </horizontal>
              </scan>
              <range>
                  <min>0.3</min>
                  <max>12</max>
              </range>
          </ray>
          <plugin name="laser_controller" filename="libgazebo_ros_ray_sensor.so">
              <ros>
                  <argument>~/out:=scan</argument>
              </ros>
              <output_type>sensor_msgs/LaserScan</output_type>
              <frame_name>laser_frame</frame_name>
          </plugin>
      </sensor>
  </gazebo>
</robot>
